Workbook

Sheet Beranda
A1: Link | B1: Fungsi
A2: =HYPERLINK("https://docs.google.com/spreadsheets/d/1ESni1h-9NP1dVdHaEILuc6WWv_P8-mWX3jXPRX9GysM/edit#gid=1979551602","BisaStok") -> BisaStok | B2: Menuliskan pembelian stok dari Kas ITBisa
A3: =HYPERLINK("https://docs.google.com/spreadsheets/d/1ESni1h-9NP1dVdHaEILuc6WWv_P8-mWX3jXPRX9GysM/edit#gid=533652570","BisaPerlengkapan") -> BisaPerlengkapan | B3: Menuliskan perlengkapan yang berhubungan dengan penjualan
A4: =HYPERLINK("https://docs.google.com/spreadsheets/d/1ESni1h-9NP1dVdHaEILuc6WWv_P8-mWX3jXPRX9GysM/edit#gid=1164177046","BisaHitungImpor") -> BisaHitungImpor
A5: =HYPERLINK("https://docs.google.com/spreadsheets/d/1ESni1h-9NP1dVdHaEILuc6WWv_P8-mWX3jXPRX9GysM/edit#gid=90517666","BisaEksporBisaJual") -> BisaEksporBisaJual
A6: =HYPERLINK("https://docs.google.com/spreadsheets/d/1ESni1h-9NP1dVdHaEILuc6WWv_P8-mWX3jXPRX9GysM/edit#gid=171163769","BisaHilang") -> BisaHilang
A7: =HYPERLINK("https://docs.google.com/spreadsheets/d/1ESni1h-9NP1dVdHaEILuc6WWv_P8-mWX3jXPRX9GysM/edit#gid=1152745648","BisaJualBukalapak") -> BisaJualBukalapak | B7: Menuliskan semua transaksi barang dari Bukalapak
A8: =HYPERLINK("https://docs.google.com/spreadsheets/d/1ESni1h-9NP1dVdHaEILuc6WWv_P8-mWX3jXPRX9GysM/edit#gid=1873910816","BisaJualTokopedia") -> BisaJualTokopedia | B8: Menuliskan semua transaksi barang dari Tokopedia
A9: =HYPERLINK("https://docs.google.com/spreadsheets/d/1ESni1h-9NP1dVdHaEILuc6WWv_P8-mWX3jXPRX9GysM/edit#gid=1921632670","BisaJualBliBli") -> BisaJualBliBli
A10: =HYPERLINK("https://docs.google.com/spreadsheets/d/1ESni1h-9NP1dVdHaEILuc6WWv_P8-mWX3jXPRX9GysM/edit#gid=1461742550","BisaJualWeb") -> BisaJualWeb
A11: =HYPERLINK("https://docs.google.com/spreadsheets/d/1ESni1h-9NP1dVdHaEILuc6WWv_P8-mWX3jXPRX9GysM/edit#gid=526519451","BisaJualCOD") -> BisaJualCOD
A12: =HYPERLINK("https://docs.google.com/spreadsheets/d/1ESni1h-9NP1dVdHaEILuc6WWv_P8-mWX3jXPRX9GysM/edit#gid=716139622","BisaSEO") -> BisaSEO

Sheet BisaStok
A1: c | D1: Pengiriman | F1: Pembelian | J1: Data Invoice | R1: USD | X1: Rp | AD1: Penjualan
A2: SKU | B2: Tanggal Bayar | C2: Tanggal Sampai | D2: Alamat Pengiriman | E2: Luar Negeri? | F2: Toko | G2: URL Beli | H2: Keterangan Pembelian | I2: Score (0 - 5) | J2: Banyak Lot | K2: Pcs per Lot | L2: HPP per Lot (USD) | M2: Ongkos Kirim (USD) | N2: Diskon Barang (USD) | O2: Diskon Ongkos Kirim (USD) | P2: Konversi USD ke Rupiah | Q2: {={"Banyak Barang (Buah)";IF(J3:J1026*K3:K1026=0,,J3:J1026*K3:K1026)}} -> Banyak Barang (Buah) | R2: {={"Total Harga Lot (USD)";IF(J3:J1026*L3:L1026=0,,J3:J1026*L3:L1026)}} -> Total Harga Lot (USD) | S2: {={"Ongkos Kirim (USD)";IF(M3:M1026=0,,M3:M1026)}} -> Ongkos Kirim (USD) | T2: {={"Diskon Barang (USD)";IF(N3:N1026=0,,N3:N1026)}} -> Diskon Barang (USD) | U2: {={"Diskon Ongkos Kirim (USD)";IF(O3:O1026=0,,O3:O1026)}} -> Diskon Ongkos Kirim (USD) | V2: {={"Total HPP (USD)";IF(R3:R1026+M3:M1026-N3:N1026-O3:O1026=0,,R3:R1026+M3:M1026-N3:N1026-O3:O1026)}} -> Total HPP (USD) | W2: {={"HPP per Buah (USD)";IF(V3:V1026=0,,V3:V1026/Q3:Q1026)}} -> HPP per Buah (USD) | X2: {={"Total Harga Lot (Rp)";IF(R3:R1026=0,,R3:R1026*P3:P1026)}} -> Total Harga Lot (Rp) | Y2: {={"Ongkos Kirim (Rp)";IF(S3:S1026*$P$3:$P1026=0,,S3:S1026*$P$3:$P1026)}} -> Ongkos Kirim (Rp) | Z2: {={"Diskon Barang (Rp)";IF(T3:T1026*$P$3:$P1026=0,,T3:T1026*$P$3:$P1026)}} -> Diskon Barang (Rp) | AA2: {={"Diskon Ongkos Kirim (Rp)";IF(U3:U1026*$P$3:$P1026=0,,U3:U1026*$P$3:$P1026)}} -> Diskon Ongkos Kirim (Rp) | AB2: {={"Total HPP (Rp)";IF(V3:V1026*$P$3:$P1026=0,,V3:V1026*$P$3:$P1026)}} -> Total HPP (Rp) | AC2: {={"HPP per Buah (Rp)";IF(AB3:AB1026=0,,AB3:AB1026/Q3:Q1026)}} -> HPP per Buah (Rp) | AD2: Harga Online/ Dropshipper (Rp) | AE2: Harga Offline (Rp) | AF2: Lain-Lain
A4: ITBISA-7SEGMENT-ANODE-RED-0.56-1BIT | B4: 45957.562 | C4: 46003.61 | D4: KYAI KONTONG | E4: TRUE | F4: Ocistok/Martkita | G4: https://detail.1688.com/offer/554814591930.html | H4: Ocistok / Martkita 302177 (0.23 RMB) | I4: 5 | J4: 7500 | K4: 1 | L4: =(672)/P4 -> 672 | M4: =(5076186 - 5040000)/P4 -> 36186 | N4: 0 | O4: =(27000/4)/P4 -> 6750 | P4: 1 | Q4: 7500 | R4: 5040000 | S4: 36186 | U4: 6750 | V4: 5069436 | W4: 675.9248 | X4: 5040000 | Y4: 36186 | AA4: 6750 | AB4: 5069436 | AC4: 675.9248
A5: ITBISA-7SEGMENT-ANODE-RED-0.56-1BIT | B5: 45858.145 | C5: 45862.567 | D5: KERTASARI CIAMIS | E5: FALSE | F5: Tokopedia | G5: Aisyah Arduino Bandung | H5: Tokopedia Anggi 2523 | I5: 5 | J5: 95 | K5: 1 | L5: =(1300)/P5 -> 0.079268293 | M5: =(1000)/P5 -> 0.06097561 | N5: =(9880 + 3137)/P5 -> 0.79371951 | O5: 0 | P5: 16400 | Q5: 95 | R5: 7.5304878 | S5: 0.06097561 | T5: 0.79371951 | V5: 6.7977439 | W5: 0.071555199 | X5: 123500 | Y5: 1000 | Z5: 13017 | AB5: 111483 | AC5: 1173.5053
A6: ITBISA-7SEGMENT-ANODE-RED-0.56-1BIT | B6: 45858.142 | C6: 45862.406 | D6: KERTASARI CIAMIS | E6: FALSE | F6: Tokopedia | G6: Aisyah Arduino Bandung | H6: Tokopedia Anggi 4347 | I6: 5 | J6: 210 | K6: 1 | L6: =(1300)/P6 -> 0.079268293 | M6: =(1000)/P6 -> 0.06097561 | N6: =(13650 + 12968)/P6 -> 1.6230488 | O6: 0 | P6: 16400 | Q6: 210 | R6: 16.646341 | S6: 0.06097561 | T6: 1.6230488 | V6: 15.084268 | W6: 0.071829849 | X6: 273000 | Y6: 1000 | Z6: 26618 | AB6: 247382 | AC6: 1178.0095
A7: ITBISA-7SEGMENT-ANODE-RED-0.56-1BIT | B7: 45374.679 | C7: 45472.771 | D7: KYAI KONTONG | E7: TRUE | F7: Ocistok/Martkita | G7: https://detail.1688.com/offer/666573965265.html | H7: Ocistok 187962 (0.24 RMB) | I7: 5 | J7: 5000 | K7: 1 | L7: =(684)/P7 -> 0.043776 | M7: 0 | N7: 0 | O7: 0 | P7: 15625 | Q7: 5000 | R7: 218.88 | V7: 218.88 | W7: 0.043776 | X7: 3420000 | AB7: 3420000 | AC7: 684
A8: ITBISA-7SEGMENT-ANODE-RED-0.56-1BIT | B8: 45371.749 | C8: 45376.653 | D8: KERTASARI CIAMIS | E8: FALSE | F8: Tokopedia | G8: Tokopedia Joko | H8: Tokopedia Joko | I8: 5 | J8: 260 | K8: 1 | L8: =(1250)/P8 -> 0.079390283 | M8: =(1000)/P8 -> 0.063512226 | N8: =(3250)/P8 -> 0.20641473 | O8: 0 | P8: 15745 | Q8: 260 | R8: 20.641473 | S8: 0.063512226 | T8: 0.20641473 | V8: 20.498571 | W8: 0.078840658 | X8: 325000 | Y8: 1000 | Z8: 3250 | AB8: 322750 | AC8: 1241.3462
A9: ITBISA-7SEGMENT-ANODE-RED-0.56-1BIT | B9: 45371.747 | C9: 45376.653 | D9: KERTASARI CIAMIS | E9: FALSE | F9: Tokopedia | G9: Tokopedia Joko | H9: Tokopedia Joko | I9: 5 | J9: 260 | K9: 1 | L9: =(1250)/P9 -> 0.079390283 | M9: =(1000)/P9 -> 0.063512226 | N9: =(5000)/P9 -> 0.31756113 | O9: 0 | P9: 15745 | Q9: 260 | R9: 20.641473 | S9: 0.063512226 | T9: 0.31756113 | V9: 20.387425 | W9: 0.078413171 | X9: 325000 | Y9: 1000 | Z9: 5000 | AB9: 321000 | AC9: 1234.6154
A10: ITBISA-7SEGMENT-ANODE-RED-0.56-1BIT | B10: 45371.745 | C10: 45376.653 | D10: KERTASARI CIAMIS | E10: FALSE | F10: Tokopedia | G10: Tokopedia Joko | H10: Tokopedia Joko | I10: 5 | J10: 260 | K10: 1 | L10: =(1250)/P10 -> 0.079390283 | M10: =(1000)/P10 -> 0.063512226 | N10: =(3250 + 5000)/P10 -> 0.52397587 | O10: 0 | P10: 15745 | Q10: 260 | R10: 20.641473 | S10: 0.063512226 | T10: 0.52397587 | V10: 20.18101 | W10: 0.077619269 | X10: 325000 | Y10: 1000 | Z10: 8250 | AB10: 317750 | AC10: 1222.1154
A11: ITBISA-7SEGMENT-ANODE-RED-0.56-1BIT | B11: 45371.744 | C11: 45376.653 | D11: KERTASARI CIAMIS | E11: FALSE | F11: Tokopedia | G11: Tokopedia Joko | H11: Tokopedia Joko | I11: 5 | J11: 260 | K11: 1 | L11: =(1250)/P11 -> 0.079390283 | M11: =(1000)/P11 -> 0.063512226 | N11: =(5000 + 12633)/P11 -> 1.1199111 | O11: 0 | P11: 15745 | Q11: 260 | R11: 20.641473 | S11: 0.063512226 | T11: 1.1199111 | V11: 19.585075 | W11: 0.07532721 | X11: 325000 | Y11: 1000 | Z11: 17633 | AB11: 308367 | AC11: 1186.0269
A12: ITBISA-7SEGMENT-ANODE-RED-0.56-1BIT | B12: 45367.612 | C12: 45371.365 | D12: KERTASARI CIAMIS | E12: FALSE | F12: Tokopedia | G12: Tokopedia Joko | H12: Tokopedia Joko | I12: 5 | J12: 260 | K12: 1 | L12: =(1240)/P12 -> 0.079283887 | M12: =(1000)/P12 -> 0.063938619 | N12: =(1612 + 12896)/P12 -> 0.92762148 | O12: 0 | P12: 15640 | Q12: 260 | R12: 20.613811 | S12: 0.063938619 | T12: 0.92762148 | V12: 19.750128 | W12: 0.07596203 | X12: 322400 | Y12: 1000 | Z12: 14508 | AB12: 308892 | AC12: 1188.0462
A13: ITBISA-7SEGMENT-ANODE-RED-0.56-1BIT | B13: 45348.692 | C13: 45350.482 | D13: KERTASARI CIAMIS | E13: FALSE | F13: Tokopedia | G13: Tokopedia Joko | H13: Tokopedia Joko | I13: 5 | J13: 450 | K13: 1 | L13: =(1240)/P13 -> 0.079299098 | M13: =(1000)/P13 -> 0.063950886 | N13: =(5580)/P13 -> 0.35684594 | O13: 0 | P13: 15637 | Q13: 450 | R13: 35.684594 | S13: 0.063950886 | T13: 0.35684594 | V13: 35.391699 | W13: 0.07864822 | X13: 558000 | Y13: 1000 | Z13: 5580 | AB13: 553420 | AC13: 1229.8222
A14: ITBISA-7SEGMENT-ANODE-RED-0.56-1BIT | B14: 45334.477 | C14: 45413.611 | D14: KYAI KONTONG | E14: TRUE | F14: Ocistok/Martkita | G14: Ocistok | I14: 5 | J14: 3000 | K14: 1 | L14: =(657)/P14 -> 0.041764668 | M14: 0 | N14: 0 | O14: 0 | P14: 15731 | Q14: 3000 | R14: 125.29401 | V14: 125.29401 | W14: 0.041764668 | X14: 1971000 | AB14: 1971000 | AC14: 657
A15: ITBISA-7SEGMENT-ANODE-RED-0.56-1BIT | B15: 45013 | C15: 45061 | D15: KYAI KONTONG | E15: TRUE | F15: Jasa Impor Tiongkok | G15: Jasa Impor Tiongkok | I15: 5 | J15: 10050 | K15: 1 | L15: =731/P15 -> 0.048519846 | M15: 0 | N15: 0 | O15: 0 | P15: 15066 | Q15: 10050 | R15: 487.62445 | V15: 487.62445 | W15: 0.048519846 | X15: 7346550 | AB15: 7346550 | AC15: 731
A16: ITBISA-7SEGMENT-ANODE-RED-0.56-1BIT | B16: 44990.805 | C16: 45361.511 | D16: KERTASARI CIAMIS | E16: FALSE | F16: Tokopedia | G16: Tokopedia Joko | H16: Tokopedia Joko | I16: 5 | J16: 260 | K16: 1 | L16: =(1240)/P16 -> 0.078730159 | M16: =(1000)/P16 -> 0.063492063 | N16: =(3224 + 1612)/P16 -> 0.30704762 | O16: 0 | P16: 15750 | Q16: 260 | R16: 20.469841 | S16: 0.063492063 | T16: 0.30704762 | V16: 20.226286 | W16: 0.077793407 | X16: 322400 | Y16: 1000 | Z16: 4836 | AB16: 318564 | AC16: 1225.2462
A17: ITBISA-7SEGMENT-ANODE-RED-0.56-1BIT | B17: 44990.802 | C17: 45361.511 | D17: KERTASARI CIAMIS | E17: FALSE | F17: Tokopedia | G17: Tokopedia Joko | H17: Tokopedia Joko | I17: 5 | J17: 260 | K17: 1 | L17: =(1240)/P17 -> 0.078730159 | M17: =(1000)/P17 -> 0.063492063 | N17: =(3224 + 5000 + 1595)/P17 -> 0.62342857 | O17: 0 | P17: 15750 | Q17: 260 | R17: 20.469841 | S17: 0.063492063 | T17: 0.62342857 | V17: 19.909905 | W17: 0.076576557 | X17: 322400 | Y17: 1000 | Z17: 9819 | AB17: 313581 | AC17: 1206.0808
A18: ITBISA-7SEGMENT-ANODE-RED-0.56-1BIT | B18: 44839 | C18: 44889 | D18: KYAI KONTONG | E18: TRUE | F18: Jasa Impor Tiongkok | G18: Jasa Impor Tiongkok | H18: Tokopedia Furqonajiy | I18: 5 | J18: 37 | K18: 150 | L18: =(1731600+6926400)/2/37/P18 -> 7.8 | M18: =1000/P18 -> 0.066666667 | N18: =(51948+500000-112525-1000)/2/P18 -> 14.6141 | O18: 0 | P18: 15000 | Q18: 5550 | R18: 288.6 | S18: 0.066666667 | T18: 14.6141 | V18: 274.05257 | W18: 0.049378841 | X18: 4329000 | Y18: 1000 | Z18: 219211.5 | AB18: 4110788.5 | AC18: 740.68261
A19: ITBISA-7SEGMENT-ANODE-RED-0.56-1BIT | B19: 44008 | C19: 44022 | D19: KAETOBO RESIDENCE | E19: TRUE | F19: Shopee | G19: https://shopee.co.id/product/36506495/7612131078 | H19: Shopee Furqonajiy 200626RH03BEN5 | I19: 4 | J19: 20 | K19: 10 | L19: =13908/P19 -> 1.3908 | M19: =12000/P19 -> 1.2 | O19: =M19 -> 1.2 | P19: 10000 | Q19: 200 | R19: 27.816 | S19: 1.2 | U19: 1.2 | V19: 27.816 | W19: 0.13908 | X19: 278160 | Y19: 12000 | AA19: 12000 | AB19: 278160 | AC19: 1390.8
A20: ITBISA-7SEGMENT-ANODE-RED-0.56-1BIT | B20: 44008 | C20: 44020 | D20: KAETOBO RESIDENCE | E20: TRUE | F20: Shopee | G20: https://shopee.co.id/product/240782907/4328806797 | H20: Shopee Furqonajiy 200626RHJJNQ1R | I20: 5 | J20: 50 | K20: 10 | L20: =13997/P20 -> 1.3997 | M20: =12000/P20 -> 1.2 | P20: 10000 | Q20: 500 | R20: 69.985 | S20: 1.2 | V20: 71.185 | W20: 0.14237 | X20: 699850 | Y20: 12000 | AB20: 711850 | AC20: 1423.7
A21: ITBISA-7SEGMENT-ANODE-RED-0.56-1BIT | B21: 43971 | C21: 43980 | D21: KAETOBO RESIDENCE | E21: TRUE | F21: Shopee | G21: https://shopee.co.id/product/240782907/4328806797?smtt=0.0.9 | H21: Shopee Furqonajiy 200428N62SUQV8 | I21: 5 | J21: 50 | K21: 10 | L21: =13997/P21 -> 1.3997 | M21: =12000/P21 -> 1.2 | P21: 10000 | Q21: 500 | R21: 69.985 | S21: 1.2 | V21: 71.185 | W21: 0.14237 | X21: 699850 | Y21: 12000 | AB21: 711850 | AC21: 1423.7
A22: ITBISA-7SEGMENT-ANODE-RED-0.56-1BIT | B22: 43887 | C22: 43987 | D22: RUMAH MUZAKKI | E22: TRUE | F22: AliExpress | G22: https://www.Aliexpress.com/item/32262476520.html?spm | H22: Aliexpress Furqonajiy 8011001562654116 | J22: 15 | K22: 50 | L22: 4.21 | P22: =899572/(4.21*15) -> 14245.004 | Q22: 750 | R22: 63.15 | V22: 63.15 | W22: 0.0842 | X22: 899572 | AB22: 899572 | AC22: 1199.4293
A23: ITBISA-7SEGMENT-ANODE-RED-0.56-1BIT | B23: 43798 | C23: 43829 | D23: RUMAH MUZAKKI | E23: TRUE | F23: AliExpress | G23: https://www.Aliexpress.com/item/50pcs-1bit-1-bit-Common-Anode-Positive-Digital-Tube-0-56-0-56in-Red-LED-Digit/32262476520.html?spm=a2g0s.9042311.0.0.334d4c4d1XLiYh | H23: Aliexpress Furqonajiy 8007001849904116 | J23: 12 | K23: 50 | L23: 4.21 | N23: 5 | P23: =1309247/(91.04) -> 14381.008 | Q23: 600 | R23: 50.52 | T23: 5 | V23: 45.52 | W23: 0.075866667 | X23: 726528.54 | Z23: 71905.042 | AB23: 654623.5 | AC23: 1091.0392
A24: ITBISA-7SEGMENT-ANODE-RED-0.56-1BIT | B24: 43782 | C24: 43810 | D24: RUMAH MUZAKKI | E24: TRUE | F24: AliExpress | G24: https://www.Aliexpress.com/item/50pcs-1bit-1-bit-Common-Anode-Positive-Digital-Tube-0-56-0-56in-Red-LED-Digit/32262476520.html?spm=a2g0s.9042311.0.0.334d4c4d1XLiYh | H24: Aliexpress Furqonajiy 8006178019124116 8006223027484116 | J24: 10 | K24: 50 | L24: 4.16 | M24: =10000/P24 -> 0.69734996 | N24: 1 | P24: =(1014125+269592)/(12*4.16+10*4.16-2) -> 14340.002 | Q24: 500 | R24: 41.6 | S24: 0.69734996 | T24: 1 | V24: 41.29735 | W24: 0.0825947 | X24: 596544.09 | Y24: 10000 | Z24: 14340.002 | AB24: 592204.09 | AC24: 1184.4082
A25: ITBISA-7SEGMENT-ANODE-RED-0.56-1BIT | B25: 43719 | C25: 43749.797 | D25: RUMAH MUZAKKI | E25: TRUE | F25: AliExpress | G25: ="https://www.aliexpress.com/item/20pcs-bag-Red-bright-LED-red-0-5-0-56-inches-a-common-cathode-shell-12/32262476520.html?spm=2114.search0104.3.136.695b58f9P8tLRf&ws_ab_test=searchweb0_0,searchweb201602_5_10065_10068_5734615_319_317_10696_453_10084_10924_45"&"4_10083_10618_10920_10921_10307_10922_537_536_10059_10884_10887_100031_321_322_10103_5734515,searchweb201603_1,ppcSwitch_0&algo_expid=ec02fe65-0b12-4543-bfac-829a7f0163f6-20&algo_pvid=ec02fe65-0b12-4543-bfac-829a7f0163f6" -> https://www.aliexpress.com/item/20pcs-bag-Red-bright-LED-red-0-5-0-56-inches-a-common-cathode-shell-12/32262476520.html?spm=2114.search0104.3.136.695b58f9P8tLRf&ws_ab_test=searchweb0_0,searchweb201602_5_10065_10068_5734615_319_317_10696_453_10084_10924_454_10083_10618_10920_10921_10307_10922_537_536_10059_10884_10887_100031_321_322_10103_5734515,searchweb201603_1,ppcSwitch_0&algo_expid=ec02fe65-0b12-4543-bfac-829a7f0163f6-20&algo_pvid=ec02fe65-0b12-4543-bfac-829a7f0163f6 | H25: Aliexpress Furqonajiy 8001779903204116 Resi EX211568265SG | J25: 12 | K25: 50 | L25: 4.35 | M25: =(20000/P25)/2+10000/P25 -> 1.3943108 | P25: =748757/(4.35*12) -> 14344.004 | Q25: 600 | R25: 52.2 | S25: 1.3943108 | V25: 53.594311 | W25: 0.089323851 | X25: 748757 | Y25: 20000 | AB25: 768757 | AC25: 1281.2617 | AE25: 1500
A26: ITBISA-7SEGMENT-ANODE-RED-0.56-1BIT | B26: 43617.966 | C26: 43639.949 | D26: RUMAH MUZAKKI | E26: TRUE | F26: AliExpress | G26: https://www.Aliexpress.com/item/50pcs-1bit-1-bit-Common-Anode-Positive-Digital-Tube-0-56-0-56in-Red-LED-Digit/32262476520.html?spm=a2g0s.9042311.0.0.3da24c4dThHZe2 | H26: Aliexpress Furqonajiy 102437170834116 Resi RP598310436CN | J26: 12 | K26: 50 | L26: 4.12 | P26: =732477/49.92 -> 14673.017 | Q26: 600 | R26: 49.44 | V26: 49.44 | W26: 0.0824 | X26: 725433.95 | AB26: 725433.95 | AC26: 1209.0566 | AD26: 1500 | AE26: 1500
A27: ITBISA-7SEGMENT-ANODE-RED-0.56-1BIT | B27: 43581 | C27: =B27 -> 43581 | D27: AVRG ITB | E27: FALSE | F27: URO Shop | G27: URO Shop | H27: URO Shop | J27: 100 | K27: 1 | L27: =1300/P27 -> 0.13 | P27: 10000 | Q27: 100 | R27: 13 | V27: 13 | W27: 0.13 | X27: 130000 | AB27: 130000 | AC27: 1300 | AE27: 1500
A28: ITBISA-7SEGMENT-ANODE-RED-0.56-1BIT | B28: 43572 | C28: 43596 | D28: RUMAH SYAFIRA | E28: TRUE | F28: AliExpress | G28: ="https://www.aliexpress.com/item/20pcs-bag-Red-bright-LED-red-0-5-0-56-inches-a-common-cathode-shell-12/32262476520.html?spm=a2g0s.12269583.0.0.109b57f2T8L4qD" -> https://www.aliexpress.com/item/20pcs-bag-Red-bright-LED-red-0-5-0-56-inches-a-common-cathode-shell-12/32262476520.html?spm=a2g0s.12269583.0.0.109b57f2T8L4qD | H28: Aliexpress Furqonajiy 100739640614116 Resi RP540582475CN | J28: 10 | K28: 50 | L28: 4.3 | M28: 0 | N28: 0 | O28: 0 | P28: =616921/(4.3*10) -> 14347 | Q28: 500 | R28: 43 | V28: 43 | W28: 0.086 | X28: 616921 | AB28: 616921 | AC28: 1233.842 | AD28: 1400 | AE28: 1500
A29: ITBISA-7SEGMENT-ANODE-RED-0.56-1BIT | B29: 43570.434 | C29: =B29 -> 43570.434 | D29: AVRG ITB | E29: FALSE | F29: URO Shop | G29: URO Shop | H29: URO Shop | J29: 160 | K29: 1 | L29: =1300/P29 -> 0.13 | M29: 0 | N29: 0 | O29: 0 | P29: 10000 | Q29: 160 | R29: 20.8 | V29: 20.8 | W29: 0.13 | X29: 208000 | AB29: 208000 | AC29: 1300 | AD29: 1400 | AE29: 1500
A30: ITBISA-7SEGMENT-ANODE-RED-0.56-1BIT | B30: 43536.484 | C30: =B30 -> 43536.484 | D30: AVRG ITB | E30: FALSE | F30: URO Shop | G30: URO Shop | H30: URO Shop | J30: 90 | K30: 1 | L30: =1300/P30 -> 0.13 | M30: 0 | P30: 10000 | Q30: 90 | R30: 11.7 | V30: 11.7 | W30: 0.13 | X30: 117000 | AB30: 117000 | AC30: 1300 | AD30: 1400 | AE30: 1500
A31: ITBISA-7SEGMENT-ANODE-RED-0.56-1BIT | B31: 43535.646 | C31: =B31 -> 43535.646 | D31: AVRG ITB | E31: FALSE | F31: URO Shop | G31: URO Shop | H31: URO Shop | J31: 25 | K31: 1 | L31: =1300/P31 -> 0.13 | M31: 0 | P31: 10000 | Q31: 25 | R31: 3.25 | V31: 3.25 | W31: 0.13 | X31: 32500 | AB31: 32500 | AC31: 1300 | AD31: 1400 | AE31: 1500
A32: ITBISA-7SEGMENT-ANODE-RED-0.56-1BIT | B32: 43530.663 | C32: 43550 | D32: RUMAH SYAFIRA | E32: TRUE | F32: AliExpress | G32: ="https://www.aliexpress.com/item/20pcs-bag-Red-bright-LED-red-0-5-0-56-inches-a-common-cathode-shell-12/32262476520.html?spm=2114.search0104.3.136.695b58f9P8tLRf&ws_ab_test=searchweb0_0,searchweb201602_5_10065_10068_5734615_319_317_10696_453_10084_10924_45"&"4_10083_10618_10920_10921_10307_10922_537_536_10059_10884_10887_100031_321_322_10103_5734515,searchweb201603_1,ppcSwitch_0&algo_expid=ec02fe65-0b12-4543-bfac-829a7f0163f6-20&algo_pvid=ec02fe65-0b12-4543-bfac-829a7f0163f6" -> https://www.aliexpress.com/item/20pcs-bag-Red-bright-LED-red-0-5-0-56-inches-a-common-cathode-shell-12/32262476520.html?spm=2114.search0104.3.136.695b58f9P8tLRf&ws_ab_test=searchweb0_0,searchweb201602_5_10065_10068_5734615_319_317_10696_453_10084_10924_454_10083_10618_10920_10921_10307_10922_537_536_10059_10884_10887_100031_321_322_10103_5734515,searchweb201603_1,ppcSwitch_0&algo_expid=ec02fe65-0b12-4543-bfac-829a7f0163f6-20&algo_pvid=ec02fe65-0b12-4543-bfac-829a7f0163f6 | H32: Aliexpress Furqonajiy 99320493804116 Resi RX470050702CN | J32: 8 | K32: 50 | L32: 4.3 | M32: 0 | N32: 0 | O32: 0 | P32: =991477/(8*4.3 + 8*4.3) -> 14411.003 | Q32: 400 | R32: 34.4 | V32: 34.4 | W32: 0.086 | X32: 495738.5 | AB32: 495738.5 | AC32: 1239.3463 | AD32: 1400 | AE32: 1500
A33: ITBISA-7SEGMENT-ANODE-RED-0.56-1BIT | B33: 43428 | C33: 43432 | D33: RUMAH SYAFIRA | E33: TRUE | F33: AliExpress | G33: ="https://www.aliexpress.com/item/20pcs-bag-Red-bright-LED-red-0-5-0-56-inches-a-common-cathode-shell-12/32262476520.html?spm=2114.search0104.3.136.695b58f9P8tLRf&ws_ab_test=searchweb0_0,searchweb201602_5_10065_10068_5734615_319_317_10696_453_10084_10924_45"&"4_10083_10618_10920_10921_10307_10922_537_536_10059_10884_10887_100031_321_322_10103_5734515,searchweb201603_1,ppcSwitch_0&algo_expid=ec02fe65-0b12-4543-bfac-829a7f0163f6-20&algo_pvid=ec02fe65-0b12-4543-bfac-829a7f0163f6" -> https://www.aliexpress.com/item/20pcs-bag-Red-bright-LED-red-0-5-0-56-inches-a-common-cathode-shell-12/32262476520.html?spm=2114.search0104.3.136.695b58f9P8tLRf&ws_ab_test=searchweb0_0,searchweb201602_5_10065_10068_5734615_319_317_10696_453_10084_10924_454_10083_10618_10920_10921_10307_10922_537_536_10059_10884_10887_100031_321_322_10103_5734515,searchweb201603_1,ppcSwitch_0&algo_expid=ec02fe65-0b12-4543-bfac-829a7f0163f6-20&algo_pvid=ec02fe65-0b12-4543-bfac-829a7f0163f6 | H33: Aliexpress Syafirapr 96593938411876 Resi UN582235825CN | J33: 2 | K33: 50 | L33: 4.25 | N33: 4 | O33: 0 | P33: =66794/(4.25*2 - 4) -> 14843.111 | Q33: 100 | R33: 8.5 | T33: 4 | V33: 4.5 | W33: 0.045 | X33: 126166.44 | Z33: 59372.444 | AB33: 66794 | AC33: 667.94 | AD33: 1300 | AE33: 1500
A34: ITBISA-7SEGMENT-ANODE-RED-0.56-1BIT | B34: 43428 | C34: 43446 | D34: RUMAH SYAFIRA | E34: TRUE | F34: AliExpress | G34: ="https://www.aliexpress.com/item/20pcs-bag-Red-bright-LED-red-0-5-0-56-inches-a-common-cathode-shell-12/32262476520.html?spm=2114.search0104.3.136.695b58f9P8tLRf&ws_ab_test=searchweb0_0,searchweb201602_5_10065_10068_5734615_319_317_10696_453_10084_10924_45"&"4_10083_10618_10920_10921_10307_10922_537_536_10059_10884_10887_100031_321_322_10103_5734515,searchweb201603_1,ppcSwitch_0&algo_expid=ec02fe65-0b12-4543-bfac-829a7f0163f6-20&algo_pvid=ec02fe65-0b12-4543-bfac-829a7f0163f6" -> https://www.aliexpress.com/item/20pcs-bag-Red-bright-LED-red-0-5-0-56-inches-a-common-cathode-shell-12/32262476520.html?spm=2114.search0104.3.136.695b58f9P8tLRf&ws_ab_test=searchweb0_0,searchweb201602_5_10065_10068_5734615_319_317_10696_453_10084_10924_454_10083_10618_10920_10921_10307_10922_537_536_10059_10884_10887_100031_321_322_10103_5734515,searchweb201603_1,ppcSwitch_0&algo_expid=ec02fe65-0b12-4543-bfac-829a7f0163f6-20&algo_pvid=ec02fe65-0b12-4543-bfac-829a7f0163f6 | H34: Aliexpress Syafirapr 96811194361876 Resi RY427709390CN | J34: 2 | K34: 50 | L34: 4.25 | N34: =2.05/2 -> 1.025 | O34: 0 | P34: =693911/(30.5*1 + (4.25*3 + 4.25*2) - 5) -> 14843.016 | Q34: 100 | R34: 8.5 | T34: 1.025 | V34: 7.475 | W34: 0.07475 | X34: 126165.64 | Z34: 15214.091 | AB34: 110951.54 | AC34: 1109.5154 | AD34: 1300 | AE34: 1500
A35: ITBISA-7SEGMENT-ANODE-RED-1.00-1BIT | B35: 45374.679 | C35: 45477.917 | D35: KYAI KONTONG | E35: TRUE | F35: Ocistok/Martkita | G35: https://detail.1688.com/offer/678795685587.html | H35: Ocistok 187963 (0.85 RMB) | I35: 5 | J35: 3000 | K35: 1 | L35: =(2000)/P35 -> 0.128 | M35: 0 | N35: 0 | O35: 0 | P35: 15625 | Q35: 3000 | R35: 384 | V35: 384 | W35: 0.128 | X35: 6000000 | AB35: 6000000 | AC35: 2000
A36: ITBISA-7SEGMENT-ANODE-RED-1.00-1BIT | B36: 45202.354 | C36: 45232.639 | D36: KYAI KONTONG | E36: TRUE | F36: Jasa Impor Tiongkok | H36: Jasa Impor Tiongkok | I36: 5 | J36: 1000 | K36: 1 | L36: =2049/P36 -> 0.13122838 | M36: 0 | N36: 0 | O36: 0 | P36: 15614 | Q36: 1000 | R36: 131.22838 | V36: 131.22838 | W36: 0.13122838 | X36: 2049000 | AB36: 2049000 | AC36: 2049
A37: ITBISA-7SEGMENT-ANODE-RED-1.20-1BIT | B37: 45863.007 | C37: 45865.733 | D37: KERTASARI CIAMIS | E37: FALSE | F37: Shopee | G37: Shiryu Store | H37: Shopee Aji 5XV6 | I37: 5 | J37: 1 | K37: 750 | L37: =(3060000)/P37 -> 187.73006 | M37: =(25000 + 1000)/P37 -> 1.595092 | N37: =(X37*12%)/P37 -> 22.527607 | O37: =(10000)/P37 -> 0.61349693 | P37: 16300 | Q37: 750 | R37: 187.73006 | S37: 1.595092 | T37: 22.527607 | U37: 0.61349693 | V37: 166.18405 | W37: 0.22157873 | X37: 3060000 | Y37: 26000 | Z37: 367200 | AA37: 10000 | AB37: 2708800 | AC37: 3611.7333
A38: ITBISA-7SEGMENT-ANODE-RED-1.20-1BIT | B38: 45772.02 | C38: 45775.468 | D38: KERTASARI CIAMIS | E38: FALSE | F38: Shopee | G38: Shiryu Store | H38: Shopee Anggi AVDN | I38: 5 | J38: 1 | K38: 750 | L38: =(3060000)/P38 -> 182.2622 | M38: =(27904 + 736)/P38 -> 1.7058788 | N38: =(X38*12%)/P38 -> 21.871463 | O38: =(20000)/P38 -> 1.1912562 | P38: 16789 | Q38: 750 | R38: 182.2622 | S38: 1.7058788 | T38: 21.871463 | U38: 1.1912562 | V38: 160.90535 | W38: 0.21454047 | X38: 3060000 | Y38: 28640 | Z38: 367200 | AA38: 20000 | AB38: 2701440 | AC38: 3601.92
A39: ITBISA-7SEGMENT-ANODE-RED-1.20-1BIT | B39: 45690.176 | C39: 45694.254 | D39: KERTASARI CIAMIS | E39: FALSE | F39: Shopee | G39: Shiryu Store | H39: Shopee Anggi DWXE | I39: 5 | J39: 1 | K39: 750 | L39: =(3060000)/P39 -> 187.73006 | M39: =(736)/P39 -> 0.045153374 | N39: =(X39*12%)/P39 -> 22.527607 | O39: 0 | P39: 16300 | Q39: 750 | R39: 187.73006 | S39: 0.045153374 | T39: 22.527607 | V39: 165.24761 | W39: 0.22033014 | X39: 3060000 | Y39: 736 | Z39: 367200 | AB39: 2693536 | AC39: 3591.3813
A40: ITBISA-7SEGMENT-ANODE-RED-1.20-1BIT | B40: 45607.757 | C40: 45611.458 | D40: KYAI KONTONG | E40: FALSE | F40: Shopee | G40: Shiryu Store | H40: Shopee Aji JNM6 | I40: 5 | J40: 1 | K40: 1700 | L40: =(6936000)/P40 -> 439.96194 | M40: =(834)/P40 -> 0.052901998 | N40: =(832320)/P40 -> 52.795433 | O40: 0 | P40: 15765 | Q40: 1700 | R40: 439.96194 | S40: 0.052901998 | T40: 52.795433 | V40: 387.21941 | W40: 0.22777612 | X40: 6936000 | Y40: 834 | Z40: 832320 | AB40: 6104514 | AC40: 3590.8906
A41: ITBISA-7SEGMENT-ANODE-RED-1.20-1BIT | B41: 45605.176 | C41: 45607.572 | D41: KYAI KONTONG | E41: FALSE | F41: Shopee | G41: Shiryu Store | H41: Shopee Aji HRK6 | I41: 5 | J41: 1 | K41: 750 | L41: =(3060000)/P41 -> 195.32746 | M41: =(694)/P41 -> 0.044299757 | N41: =(244800)/P41 -> 15.626197 | O41: 0 | P41: 15666 | Q41: 750 | R41: 195.32746 | S41: 0.044299757 | T41: 15.626197 | V41: 179.74556 | W41: 0.23966075 | X41: 3060000 | Y41: 694 | Z41: 244800 | AB41: 2815894 | AC41: 3754.5253
...

Sheet BisaHilang
A1: Tanggal Pengecekan Kehilangan | B1: SKU | C1: Banyak Ketemu | D1: Nilai Ketemu | E1: Banyak Hilang | F1: Nilai Hilang | G1: Lokasi Gudang | H1: Keterangan
A3: 43515.59 | B3: ITBISA-IC-NE555P-DIP8 | E3: 130 | F3: =E3*385.058418171057 -> 50057.594 | G3: AVRG ITB
A5: 43550 | B5: ITBISA-JUMPER-FF-10CM | E5: 220 | F5: =E5*263.610082277654 -> 57994.218 | G5: AVRG ITB
A6: 43550.8 | B6: ITBISA-IC-NE555P-DIP8 | C6: 76 | D6: =C6*386.176666666667 -> 29349.427 | G6: AVRG ITB
A7: 43550.813 | B7: ITBISA-SOCKET-IC-DIP8-NARROW | C7: 15 | D7: =C7*279.488315084029 -> 4192.3247 | G7: AVRG ITB
A8: 43550.814 | B8: ITBISA-NPN-2N2222-TO92 | E8: 12 | F8: =E8*106.611587323364 -> 1279.339 | G8: AVRG ITB
A9: 43550.815 | B9: ITBISA-JUMPER-MF-10CM | E9: 20 | F9: =E9*263.610082277654 -> 5272.2016 | G9: AVRG ITB
A10: 43552 | B10: ITBISA-ARDUINO-UNO-R3-CLONE-CABLE30CM | E10: 1 | F10: =E10*42471.2827548361 -> 42471.283 | G10: RUMAH MUZAKKI
A11: 43552 | B11: ITBISA-ARDUINO-UNO-R3-328P-SMD | C11: 1 | D11: =C11*(42471.2827548361-5000) -> 37471.283 | G11: RUMAH MUZAKKI
A12: 43552 | B12: ITBISA-USB-A-TO-B-30CM | C12: 1 | D12: =C12*5000 -> 5000 | G12: RUMAH MUZAKKI
A13: 43552 | B13: ITBISA-ARDUINO-UNO-R3-CLONE-CABLE30CM | E13: 1 | F13: =E13*44927.11 -> 44927.11 | G13: RUMAH MUZAKKI
A14: 43552 | B14: ITBISA-ARDUINO-UNO-R3-328P-SMD | C14: 1 | D14: =C14*(44927.11-5000) -> 39927.11 | G14: RUMAH MUZAKKI
A15: 43552 | B15: ITBISA-USB-A-TO-B-30CM | C15: 1 | D15: =C15*5000 -> 5000 | G15: RUMAH MUZAKKI
A17: 43559 | B17: ITBISA-ARDUINO-UNO-R3-CLONE-CABLE30CM | E17: 1 | F17: =E17*46371.7066813006 -> 46371.707 | G17: RUMAH MUZAKKI
A18: 43559 | B18: ITBISA-ARDUINO-UNO-R3-328P-SMD | C18: 1 | D18: =C18*(46371.7066813006-5000) -> 41371.707 | G18: RUMAH MUZAKKI
A19: 43559 | B19: ITBISA-USB-A-TO-B-30CM | C19: 1 | D19: =C19*5000 -> 5000 | G19: RUMAH MUZAKKI
A20: 43563 | B20: ITBISA-ARDUINO-UNO-R3-CLONE-CABLE50CM | E20: 13 | F20: =E20*39217.1538461538 -> 509823 | G20: RUMAH MUZAKKI
A21: 43563 | B21: ITBISA-ARDUINO-UNO-R3-328P-SMD | C21: 13 | D21: =C21*(39217.1538461538-5000) -> 444823 | G21: RUMAH MUZAKKI
A22: 43563 | B22: ITBISA-USB-A-TO-B-50CM | C22: 13 | D22: =C22*5000 -> 65000 | G22: RUMAH MUZAKKI
A23: 43571 | B23: ITBISA-ARDUINO-UNO-R3-CLONE-CABLE30CM | E23: 7 | F23: =E23*38232.1428571429 -> 267625 | G23: RUMAH SYAFIRA
A24: 43571 | B24: ITBISA-ARDUINO-UNO-R3-328P-SMD | C24: 7 | D24: =C24*(38232.1428571429-5000) -> 232625 | G24: RUMAH MUZAKKI
A25: 43571 | B25: ITBISA-USB-A-TO-B-30CM | C25: 7 | D25: =C25*5000 -> 35000 | G25: RUMAH MUZAKKI
A26: 43573.954 | B26: ITBISA-JUMPER-MF-10CM | E26: 31 | F26: =E26*263.610082277654 -> 8171.9126 | G26: AVRG ITB
A27: 43573.954 | B27: ITBISA-JUMPER-FF-10CM | E27: 26 | F27: =E27*263.610082277654 -> 6853.8621 | G27: AVRG ITB
A28: 43573.955 | B28: ITBISA-IC-NE555P-DIP8 | C28: 201 | D28: =C28*376.321111111111 -> 75640.543 | G28: AVRG ITB
A30: 43617.526 | B30: ITBISA-7SEGMENT-ANODE-RED-0.56-1BIT | E30: 10 | F30: =E30*1233.842 -> 12338.42 | G30: AVRG ITB
A31: 43617.527 | B31: ITBISA-7SEGMENT-CATHODE-RED-0.56-1BIT | E31: 90 | F31: =E31*1233.842 -> 111045.78 | G31: AVRG ITB
A32: 43617.527 | B32: ITBISA-7SEGMENT-CATHODE-RED-0.56-1BIT | E32: 10 | F32: =E32*1233.842 -> 12338.42 | G32: RUMAH MUZAKKI
A33: 43617.528 | B33: ITBISA-ABC-BATERAI-D-POWER | C33: 8 | D33: =C33*3650 -> 29200 | G33: AVRG ITB
A34: 43617.529 | B34: ITBISA-USB-A-TO-B-30CM | C34: 3 | D34: =C34*5000 -> 15000 | G34: RUMAH MUZAKKI
A35: 43617.529 | B35: ITBISA-IC-NE555P-DIP8 | E35: 134 | F35: =E35*376.321111111111 -> 50427.029 | G35: AVRG ITB
A36: 43617.53 | B36: ITBISA-IC-UA741CN-DIP8 | E36: 19 | F36: =E36*688 -> 13072 | G36: AVRG ITB
A37: 43617.531 | B37: ITBISA-JUMPER-FF-10CM | C37: 80 | D37: =C37*152.785222260732 -> 12222.818 | G37: AVRG ITB
A38: 43617.531 | B38: ITBISA-JUMPER-MF-10CM | E38: 47 | F38: =E38*160.403626904782 -> 7538.9705 | G38: AVRG ITB
A39: 43617.532 | B39: ITBISA-JUMPER-FF-10CM | C39: 160 | D39: =C39*152.785222260732 -> 24445.636 | G39: RUMAH MUZAKKI
A40: 43617.533 | B40: ITBISA-JUMPER-MF-10CM | C40: 41 | D40: =C40*160.403626904782 -> 6576.5487 | G40: RUMAH MUZAKKI
A41: 43617.534 | B41: ITBISA-NPN-2N2222-TO92 | E41: 699 | F41: =E41*104.929 -> 73345.371 | G41: AVRG ITB
A42: 43617.535 | B42: ITBISA-SOCKET-IC-DIP8-NARROW | E42: 1 | F42: =E42*300 -> 300 | G42: RUMAH MUZAKKI
A44: 43678 | B44: ITBISA-TIGERHEAD-SENTER-KUNING-FT300 | C44: 2 | D44: =C44*13100 -> 26200 | G44: RUMAH MUZAKKI
A46: 43834 | B46: ITBISA-IC-NE555P-DIP8 | E46: 19 | F46: =E46*343.532091698318 -> 6527.1097 | G46: AVRG ITB
...

Sheet BisaRekapBarang
D1: TRUE | E1: FALSE | F1: FALSE | G1: FALSE | H1: FALSE | I1: FALSE | J1: FALSE | K1: FALSE | L1: FALSE | M1: FALSE | N1: FALSE | O1: FALSE | P1: FALSE | Q1: FALSE | R1: FALSE | S1: FALSE | T1: FALSE | U1: FALSE | V1: FALSE | W1: FALSE | X1: FALSE | Y1: FALSE
A2: {={BisaRekapBarangBackend!A1:C1;SORT(IF(BisaRekapBarangBackend!B2:B145<1,,BisaRekapBarangBackend!A2:C145),1,TRUE)}} -> #VALUE! | D2: {={BisaRekapBarangBackend!D1:O1; SORT(IF( (BisaRekapBarangBackend!D2:D145="ITBISA-KODE-UNIK")+(BisaRekapBarangBackend!H2:H145=0),,BisaRekapBarangBackend!D2:O145), IF(D1=TRUE,1, IF(E1=TRUE,2, IF(F1=TRUE,3, IF(G1=TRUE,4, IF(H1=TRUE,5, IF(I1=TRUE,6, IF(J1=TRUE,7, IF(K1=TRUE,8, IF(L1=TRUE,9, IF(M1=TRUE,10, IF(N1=TRUE,11, IF(#REF!=TRUE,12,1)))))))))))), IF(D1=TRUE,TRUE, IF(E1=TRUE,TRUE, IF(F1=TRUE,TRUE, IF(G1=TRUE,FALSE, IF(H1=TRUE,FALSE, IF(I1=TRUE,FALSE, IF(J1=TRUE,FALSE, IF(K1=TRUE,FALSE, IF(L1=TRUE,FALSE, IF(M1=TRUE,FALSE, IF(N1=TRUE,FALSE, IF(#REF!=TRUE,FALSE)))))))))))), 1,TRUE)}} -> SKU | E2: Tanggal Pesan Terakhir | F2: HPP Terakhir | G2: HPP Belum Terjual | H2: Total Stok | I2: 1/2 Total Stok | J2: 1/3 Total Stok | K2: 40% Total Stok | L2: 20% Total Stok | M2: KERTASARI CIAMIS | N2: KYAI KONTONG
D3: ITBISA-7SEGMENT-ANODE-RED-0.56-1BIT | E3: 46014 | F3: 675.9248 | G3: 4937630.7 | H3: 7305 | I3: 3652 | J3: 2435 | K3: 2922 | L3: 1461 | M3: 255 | N3: 7050
D4: ITBISA-7SEGMENT-ANODE-RED-1.00-1BIT | E4: 46003 | F4: 2000 | G4: 4318000 | H4: 2159 | I4: 1079 | J4: 719 | K4: 863 | L4: 431 | M4: 519 | N4: 1640
D5: ITBISA-7SEGMENT-ANODE-RED-1.20-1BIT | E5: 46006 | F5: 3611.7333 | G5: 7646039.5 | H5: 2117 | I5: 1058 | J5: 705 | K5: 846 | L5: 423 | M5: 782 | N5: 1335
D6: ITBISA-7SEGMENT-CATHODE-RED-0.56-1BIT | E6: 46020 | F6: 731 | G6: 2095046 | H6: 2866 | I6: 1433 | J6: 955 | K6: 1146 | L6: 573 | M6: 1752 | N6: 1114
D7: ITBISA-7SEGMENT-CATHODE-RED-1.20-1BIT | E7: 46000 | F7: 2756 | G7: 1113424 | H7: 404 | I7: 202 | J7: 134 | K7: 161 | L7: 80 | M7: 87 | N7: 317
D8: ITBISA-7SEGMENT-CATHODE-RED-2.30-1BIT | E8: 46022 | F8: 6028 | G8: 361680 | H8: 60 | I8: 30 | J8: 20 | K8: 24 | L8: 12 | M8: 8 | N8: 52
D9: ITBISA-ABC-BATERAI-9V-POWER | E9: 46019 | F9: 11211 | G9: 100899 | H9: 9 | I9: 4 | J9: 3 | K9: 3 | L9: 1 | M9: 8 | N9: 1
D10: ITBISA-ABC-BATERAI-AA-ALKALINE | E10: 46022 | F10: 3845.4566 | G10: 4014656.7 | H10: 1044 | I10: 522 | J10: 348 | K10: 417 | L10: 208 | M10: 250 | N10: 794
D11: ITBISA-ABC-BATERAI-AAA-ALKALINE | E11: 46020 | F11: 3612.5312 | G11: 5086444 | H11: 1408 | I11: 704 | J11: 469 | K11: 563 | L11: 281 | M11: 35 | N11: 1373
D12: ITBISA-ABC-BATERAI-D-POWER | E12: 45841 | F12: 5166.6667 | G12: 5166.6667 | H12: 1 | I12: 0 | J12: 0 | K12: 0 | L12: 0 | N12: 1
D13: ITBISA-ARDUINO-UNO-R3-328P-SMD | E13: 45997 | F13: 37978.259 | G13: 9912325.7 | H13: 261 | I13: 130 | J13: 87 | K13: 104 | L13: 52 | M13: 221 | N13: 40
D14: ITBISA-BLUETOOTH-MODULE-HC05 | E14: 46011 | F14: 29027.08 | G14: 1277191.5 | H14: 44 | I14: 22 | J14: 14 | K14: 17 | L14: 8 | M14: 6 | N14: 38
D15: ITBISA-BREADBOARD-830HOLE-MB102 | E15: 46015 | F15: 7000 | G15: 203000 | H15: 29 | I15: 14 | J15: 9 | K15: 11 | L15: 5 | M15: 24 | N15: 5
D16: ITBISA-BUBBLE-WRAP | E16: 46000 | G16: 0 | H16: -13 | I16: -6 | J16: -4 | K16: -5 | L16: -2 | M16: -11 | N16: -2
D17: ITBISA-BUZZER-ACTIVE-5V | E17: 46019 | F17: 1170.311 | G17: 3715737.4 | H17: 3175 | I17: 1587 | J17: 1058 | K17: 1270 | L17: 635 | M17: 1037 | N17: 2138
D18: ITBISA-CHIP-ESP32-WROOM | E18: 46016 | F18: 23076 | G18: 392292 | H18: 17 | I18: 8 | J18: 5 | K18: 6 | L18: 3 | M18: 22 | N18: -5
D19: ITBISA-CHIP-ESP32-WROOM-ANTENNA | F19: 24820 | G19: 198560 | H19: 8 | I19: 4 | J19: 2 | K19: 3 | L19: 1 | N19: 8
D20: ITBISA-CHIP-ESP8266-ESP12F | E20: 45981 | F20: 13937.05 | G20: 1951187 | H20: 140 | I20: 70 | J20: 46 | K20: 56 | L20: 28 | M20: 138 | N20: 2
D21: ITBISA-DC-TO-DC-STEPDOWN-LM2596 | E21: 46015 | F21: 4973.93 | G21: 1124108.2 | H21: 226 | I21: 113 | J21: 75 | K21: 90 | L21: 45 | M21: 101 | N21: 125
D22: ITBISA-DC-TO-DC-STEPDOWN-XL4005 | E22: 46000 | F22: 8461.025 | G22: 1167621.4 | H22: 138 | I22: 69 | J22: 46 | K22: 55 | L22: 27 | M22: 67 | N22: 71
D23: ITBISA-DC-TO-DC-STEPDOWN-XL4015 | E23: 46015 | F23: 8384.9833 | G23: 1442217.1 | H23: 172 | I23: 86 | J23: 57 | K23: 68 | L23: 34 | M23: 119 | N23: 53
D24: ITBISA-DC-TO-DC-STEPUP-XL6009 | E24: 46022 | F24: 6910.9 | G24: 1921230.2 | H24: 278 | I24: 139 | J24: 92 | K24: 111 | L24: 55 | M24: 186 | N24: 92
D25: ITBISA-I2C-IIC-LCD | E25: 46022 | F25: 5617.6 | G25: 381996.8 | H25: 68 | I25: 34 | J25: 22 | K25: 27 | L25: 13 | M25: 31 | N25: 37
D26: ITBISA-IC-74HC595N-DIP16 | E26: 46022 | F26: 639.424 | G26: 2611407.6 | H26: 4084 | I26: 2042 | J26: 1361 | K26: 1633 | L26: 816 | M26: 14 | N26: 4070
D27: ITBISA-IC-ATMEGA328P-DIP28 | E27: 46015 | F27: 27318.462 | G27: 5190507.7 | H27: 190 | I27: 95 | J27: 63 | K27: 76 | L27: 38 | M27: 159 | N27: 31
D28: ITBISA-IC-CD4017BE-DIP16 | E28: 46016 | F28: 727.964 | G28: 3760662 | H28: 5166 | I28: 2583 | J28: 1722 | K28: 2066 | L28: 1033 | N28: 5166
D29: ITBISA-IC-CD4094BE-DIP16 | E29: 45709 | F29: 779.544 | G29: 7795440 | H29: 10000 | I29: 5000 | J29: 3333 | K29: 4000 | L29: 2000 | N29: 10000
D30: ITBISA-IC-CD4094BM-SMD-SOP16 | E30: 46020 | F30: 874.83483 | G30: 762855.98 | H30: 872 | I30: 436 | J30: 290 | K30: 348 | L30: 174 | M30: 494 | N30: 378
D31: ITBISA-IC-JRC4558D-DIP8 | E31: 46017 | F31: 552.98952 | G31: 1498048.6 | H31: 2709 | I31: 1354 | J31: 903 | K31: 1083 | L31: 541 | M31: 1000 | N31: 1709
D32: ITBISA-IC-L7805CV-TO220 | E32: 46013 | F32: 1140.7243 | G32: 5168622 | H32: 4531 | I32: 2265 | J32: 1510 | K32: 1812 | L32: 906 | M32: 932 | N32: 3599
D33: ITBISA-IC-L7812CV-TO220 | E33: 46019 | F33: 1057 | G33: 1144731 | H33: 1083 | I33: 541 | J33: 361 | K33: 433 | L33: 216 | M33: 802 | N33: 281
D34: ITBISA-IC-LM741CN-DIP8 | E34: 45965 | F34: 1291.1 | G34: 27113.1 | H34: 21 | I34: 10 | J34: 7 | K34: 8 | L34: 4 | N34: 21
D35: ITBISA-IC-NE555P-DIP8 | E35: 46022 | F35: 288.887 | G35: 1521567.8 | H35: 5267 | I35: 2633 | J35: 1755 | K35: 2106 | L35: 1053 | M35: 2992 | N35: 2275
D36: ITBISA-IC-PC817-DIP4 | E36: 46022 | F36: 340.3485 | G36: 1347099.4 | H36: 3958 | I36: 1979 | J36: 1319 | K36: 1583 | L36: 791 | M36: 1748 | N36: 2210
D37: ITBISA-IC-UA741CN-DIP8 | E37: 46022 | F37: 572 | G37: 2864004 | H37: 5007 | I37: 2503 | J37: 1669 | K37: 2002 | L37: 1001 | M37: 4619 | N37: 388
D38: ITBISA-IC-ULN2003AN-DIP16 | E38: 46021 | F38: 855.5 | G38: 2073732 | H38: 2424 | I38: 1212 | J38: 808 | K38: 969 | L38: 484 | M38: 1214 | N38: 1210
D39: ITBISA-IC-ULN2803APG-DIP18 | E39: 46021 | F39: 1018 | G39: 1344778 | H39: 1321 | I39: 660 | J39: 440 | K39: 528 | L39: 264 | M39: 423 | N39: 898
D40: ITBISA-IDC-2X5-AMPHENOL-FEMALE | E40: 46016 | F40: 730 | G40: 886950 | H40: 1215 | I40: 607 | J40: 405 | K40: 486 | L40: 243 | M40: 1021 | N40: 194
...

Sheet BisaPindahBarang
A1: Tanggal | B1: SKU | C1: Lokasi Penambahan Barang | D1: Lokasi Pengurangan Barang | E1: Banyak Barang | F1: Keterangan
A3: 43595 | B3: ITBISA-7SEGMENT-ANODE-RED-0.56-1BIT | C3: AVRG ITB | D3: RUMAH SYAFIRA | E3: 1100
A4: 43595 | B4: ITBISA-7SEGMENT-ANODE-RED-2.30-1BIT | C4: AVRG ITB | D4: RUMAH MUZAKKI | E4: 10
A5: 43595 | B5: ITBISA-7SEGMENT-CATHODE-RED-0.56-1BIT | C5: AVRG ITB | D5: RUMAH SYAFIRA | E5: 750
A6: 43595 | B6: ITBISA-7SEGMENT-CATHODE-RED-0.56-1BIT | C6: AVRG ITB | D6: WARUNG IBU | E6: 150
A7: 43595 | B7: ITBISA-ABC-BATERAI-D-BIRU | C7: AVRG ITB | E7: 60
A8: 43595 | B8: ITBISA-ABC-BATERAI-D-POWER | C8: AVRG ITB | D8: RUMAH MUZAKKI | E8: 40
A9: 43595 | B9: ITBISA-ABC-BATERAI-D-POWER | C9: AVRG ITB | D9: WARUNG IBU | E9: 60
A10: 43595 | B10: ITBISA-ARDUINO-UNO-R3-328P-SMD | C10: AVRG ITB | D10: RUMAH MUZAKKI | E10: 7
A11: 43595 | B11: ITBISA-USB-A-TO-B-30CM | C11: AVRG ITB | D11: RUMAH MUZAKKI | E11: 7
A12: 43595 | B12: ITBISA-ARDUINO-UNO-R3-328P-SMD | C12: AVRG ITB | D12: RUMAH MUZAKKI | E12: 3
A13: 43595 | B13: ITBISA-USB-A-TO-B-30CM | C13: AVRG ITB | D13: RUMAH MUZAKKI | E13: 3
A14: 43595 | B14: ITBISA-ARDUINO-UNO-R3-328P-SMD | C14: AVRG ITB | D14: RUMAH MUZAKKI | E14: 13
A15: 43595 | B15: ITBISA-USB-A-TO-B-50CM | C15: AVRG ITB | D15: RUMAH MUZAKKI | E15: 13
A16: 43595 | B16: ITBISA-EPSON-L310 | C16: AVRG ITB | D16: RUMAH MUZAKKI | E16: 1
A17: 43595 | B17: ITBISA-IC-NE555P-DIP8 | C17: AVRG ITB | D17: WARUNG IBU | E17: 4900
A18: 43595 | B18: ITBISA-IC-NE555P-DIP8 | C18: AVRG ITB | D18: RUMAH MUZAKKI | E18: 1500
A19: 43595 | B19: ITBISA-IC-UA741CN-DIP8 | C19: AVRG ITB | D19: RUMAH SYAFIRA | E19: 1500
... A254: 45004 | B254: ITBISA-IC-CD4017BE-DIP16 | C254: KERTASARI CIAMIS | D254: KYAI KONTONG | E254: 1000
A255: 45004 | B255: ITBISA-7SEGMENT-ANODE-RED-0.56-1BIT | C255: KERTASARI CIAMIS | D255: KYAI KONTONG | E255: =5*150 -> 750
A256: 45004 | B256: ITBISA-7SEGMENT-CATHODE-RED-0.56-1BIT | C256: KERTASARI CIAMIS | D256: KYAI KONTONG | E256: =7*150 -> 1050
A257: 45004 | B257: ITBISA-IC-L7805CV-TO220 | C257: KERTASARI CIAMIS | D257: KYAI KONTONG | E257: 1000
A258: 45050 | B258: ITBISA-7SEGMENT-CATHODE-RED-0.56-1BIT | C258: KYAI KONTONG | D258: KERTASARI CIAMIS | E258: 4
A259: 45056 | B259: ITBISA-IC-CD4017BE-DIP16 | C259: KYAI KONTONG | D259: KERTASARI CIAMIS | E259: 100
A260: 45058 | B260: ITBISA-IC-NE555P-DIP8 | C260: KYAI KONTONG | D260: KERTASARI CIAMIS | E260: 100
A261: 45058 | B261: ITBISA-IC-CD4017BE-DIP16 | C261: KYAI KONTONG | D261: KERTASARI CIAMIS | E261: 100
A262: 45081 | B262: ITBISA-IC-CD4017BE-DIP16 | C262: KYAI KONTONG | D262: KERTASARI CIAMIS | E262: 23
A263: 45081 | B263: ITBISA-IC-NE555P-DIP8 | C263: KYAI KONTONG | D263: KERTASARI CIAMIS | E263: 100
A264: 45122 | B264: ITBISA-7SEGMENT-CATHODE-RED-0.56-1BIT | C264: KYAI KONTONG | D264: KERTASARI CIAMIS | E264: 60
A265: 45146 | B265: ITBISA-SOCKET-IC-DIP8-NARROW | C265: KYAI KONTONG | D265: KERTASARI CIAMIS | E265: 17
A266: 45192 | B266: ITBISA-IC-CD4094BE-DIP16 | C266: KERTASARI CIAMIS | D266: KYAI KONTONG | E266: 1000
A268: 45201.625 | B268: ITBISA-IC-NE555P-DIP8 | C268: KYAI KONTONG | D268: KERTASARI CIAMIS | E268: 50
A269: 45201.625 | B269: ITBISA-IC-74HC595N-DIP16 | C269: KYAI KONTONG | D269: KERTASARI CIAMIS | E269: 75
... A272: 45201.625 | B272: ITBISA-7SEGMENT-ANODE-RED-0.56-1BIT | C272: KERTASARI CIAMIS | D272: KYAI KONTONG | E272: 118
A273: 45203.751 | B273: ITBISA-IC-74HC245N-DIP20 | C273: KERTASARI CIAMIS | D273: KYAI KONTONG | E273: 720 | F273: INV/20231004/MPL/3492512198 Pindah 720 x 74HC245N ke Ciamis
A274: 45203.754 | B274: ITBISA-IC-UA741CN-DIP8 | C274: KERTASARI CIAMIS | D274: KYAI KONTONG | E274: 2000 | F274: INV/20231004/MPL/3492517923 Pindah 2000 x UA741CN ke Ciamis
A275: 45215.532 | B275: ITBISA-IC-74HC595N-DIP16 | C275: KYAI KONTONG | D275: KERTASARI CIAMIS | E275: 670 | F275: 2310163W3KVQHW Pengiriman 670 x 74HC595N ke Irkham Elektronik
A276: 45227.589 | B276: ITBISA-IC-CD4094BM-SMD-SOP16 | C276: KERTASARI CIAMIS | D276: KYAI KONTONG | E276: 2500
A277: 45227.589 | B277: ITBISA-7SEGMENT-ANODE-RED-0.56-1BIT | C277: KERTASARI CIAMIS | D277: KYAI KONTONG | E277: 300
A278: 45228.85 | B278: ITBISA-7SEGMENT-ANODE-RED-0.56-1BIT | C278: KERTASARI CIAMIS | D278: KYAI KONTONG | E278: 450
...

Sheet BisaSEO
A1: SKU | B1: Kata Kunci Utama | C1: Jenis Barang | D1: Keterangan Barang (Ukuran, Warna) | E1: Fungsi Barang (Opsional) | F1: Typo | G1: BisaDivisi | H1: Massa (g) | I1: Tagar | J1: {={"Hitung Tagar";IF(I2:I974="",,LEN(I2:I974)-LEN(SUBSTITUTE(I2:I974,"#","")))}} -> Hitung Tagar | K1: {={"Nama Lengkap";IF(G2:G974="",, TRIM("ITBisa - "&IF(B2:B974="",,B2:B974)&" "&IF(C2:C974="",,C2:C974 )&" "&IF(D2:D974="",,D2:D974)& " "&IF(E2:E974="",,E2:E974)&" "&IF(F2:F974="",,F2:F974)))}} -> Nama Lengkap | L1: {={"Nama Tokopedia (70 Karakter)";IF(K2:K974="",,LEFT(TRIM(K2:K974),70))}} -> Nama Tokopedia (70 Karakter) | M1: {={"Nama Bukalapak (150 Karakter)";IF(K2:K974="",,LEFT(TRIM(K2:K974),150))}} -> Nama Bukalapak (150 Karakter) | N1: {={"Nama Shopee (255 Karakter)";IF(K2:K974="",,LEFT(TRIM(K2:K974),255))}} -> Nama Shopee (255 Karakter) | O1: Link Bukalapak | P1: Link Tokopedia | Q1: Link Shopee
A2: ITBISA-7SEGMENT-ANODE-RED-0.56-1BIT | B2: Seven 7 Segment | C2: CA Common Anode | D2: 0.56 Inch Red 1BIT | E2: LED Merah Display Jam Digital Nilai Sensor | F2: 7-Segment Anoda 0,56" Inci 0.56" 0.56inch 1 BIT | G2: BisaElektronika - BisaSegment | H2: 3 | I2: #ITBisa #BisaElektronika #BisaSegment #7Segment #Segment #CA #CC #Anode #Cathode #0.56 #LED #1BIT #Red #Arduino #Counter #Digital #IC #Mikrokontroler #Timer #Clock | J2: 20 | K2: ITBisa - Seven 7 Segment CA Common Anode 0.56 Inch Red 1BIT LED Merah Display Jam Digital Nilai Sensor 7-Segment Anoda 0,56" Inci 0.56" 0.56inch 1 BIT | L2: ITBisa - Seven 7 Segment CA Common Anode 0.56 Inch Red 1BIT LED Merah | M2: ITBisa - Seven 7 Segment CA Common Anode 0.56 Inch Red 1BIT LED Merah Display Jam Digital Nilai Sensor 7-Segment Anoda 0,56" Inci 0.56" 0.56inch 1 BIT | N2: ITBisa - Seven 7 Segment CA Common Anode 0.56 Inch Red 1BIT LED Merah Display Jam Digital Nilai Sensor 7-Segment Anoda 0,56" Inci 0.56" 0.56inch 1 BIT | O2: https://www.bukalapak.com/p/elektronik/komponen-elektronik/12cm7sr-jual-itbisa-7-segment-cc-common-katoda-0-56-inci-merah-1-bit-led-display-jam-digital-nilai-sensor-7-segment-seven-red-cathode-0-56inch-inch-1bit | P2: https://tokopedia.com/itbisa/itbisa-seven-7-segment-cc-common-cathode-0-56-inch-red-1bit-merah
A3: ITBISA-7SEGMENT-ANODE-RED-1.00-1BIT | B3: Seven 7 Segment | C3: CA Common Anode | D3: 1 Inch Red 1BIT | E3: LED Merah Display Jam Digital Nilai Sensor | F3: 7-Segment Anoda 1" Inch 1inch BIT | G3: BisaElektronika - BisaSegment | H3: 3 | K3: ITBisa - Seven 7 Segment CA Common Anode 1 Inch Red 1BIT LED Merah Display Jam Digital Nilai Sensor 7-Segment Anoda 1" Inch 1inch BIT | L3: ITBisa - Seven 7 Segment CA Common Anode 1 Inch Red 1BIT LED Merah Dis | M3: ITBisa - Seven 7 Segment CA Common Anode 1 Inch Red 1BIT LED Merah Display Jam Digital Nilai Sensor 7-Segment Anoda 1" Inch 1inch BIT | N3: ITBisa - Seven 7 Segment CA Common Anode 1 Inch Red 1BIT LED Merah Display Jam Digital Nilai Sensor 7-Segment Anoda 1" Inch 1inch BIT | O3: https://www.bukalapak.com/p/elektronik/komponen-elektronik/12cn11o-jual-itbisa-ic-ua741cn-dip-8-op-amp-filter-penguat-lpf-hpf-bpf-integrated-circuit-ua-741-ua741-op-amp-opamp-8-pin-kaki-dip8-8dip
A4: ITBISA-7SEGMENT-ANODE-RED-1.20-1BIT | B4: Seven 7 Segment | C4: CA Common Anode | D4: 1.2 Inch Red 1BIT | E4: LED Merah Display Jam Digital Nilai Sensor | F4: 7-Segment Anoda 1,2" Inci 1.2" 1.2inch 1 BIT | G4: BisaElektronika - BisaSegment | H4: 3 | I4: #ITBisa #BisaElektronika #BisaSegment #7Segment #Segment #CA #CC #Anode #Cathode #0.56 #LED #1BIT #Red #Arduino #Counter #Digital #IC #Mikrokontroler #Timer #Clock | J4: 20 | K4: ITBisa - Seven 7 Segment CA Common Anode 1.2 Inch Red 1BIT LED Merah Display Jam Digital Nilai Sensor 7-Segment Anoda 1,2" Inci 1.2" 1.2inch 1 BIT | L4: ITBisa - Seven 7 Segment CA Common Anode 1.2 Inch Red 1BIT LED Merah D | M4: ITBisa - Seven 7 Segment CA Common Anode 1.2 Inch Red 1BIT LED Merah Display Jam Digital Nilai Sensor 7-Segment Anoda 1,2" Inci 1.2" 1.2inch 1 BIT | N4: ITBisa - Seven 7 Segment CA Common Anode 1.2 Inch Red 1BIT LED Merah Display Jam Digital Nilai Sensor 7-Segment Anoda 1,2" Inci 1.2" 1.2inch 1 BIT
A5: ITBISA-7SEGMENT-ANODE-RED-2.30-1BIT | B5: Seven 7 Segment | C5: HS 23101 BS CA Anode Jam Masjid | D5: 2.30 Inch Red 1BIT | E5: LED Display Digital | F5: 7-Segment Anoda 2,3" Inci 2.3" 2.3inch 1 BIT | G5: BisaElektronika - BisaSegment | I5: #ITBisa #BisaElektronika #BisaSegment #7Segment #Segment #CA #CC #Anode #Cathode #0.56 #LED #1BIT #Red #Arduino #Counter #Digital #IC #Mikrokontroler #Timer #Clock | J5: 20 | K5: ITBisa - Seven 7 Segment HS 23101 BS CA Anode Jam Masjid 2.30 Inch Red 1BIT LED Display Digital 7-Segment Anoda 2,3" Inci 2.3" 2.3inch 1 BIT | L5: ITBisa - Seven 7 Segment HS 23101 BS CA Anode Jam Masjid 2.30 Inch Red | M5: ITBisa - Seven 7 Segment HS 23101 BS CA Anode Jam Masjid 2.30 Inch Red 1BIT LED Display Digital 7-Segment Anoda 2,3" Inci 2.3" 2.3inch 1 BIT | N5: ITBisa - Seven 7 Segment HS 23101 BS CA Anode Jam Masjid 2.30 Inch Red 1BIT LED Display Digital 7-Segment Anoda 2,3" Inci 2.3" 2.3inch 1 BIT
A6: ITBISA-7SEGMENT-CATHODE-RED-0.56-1BIT | B6: Seven 7 Segment | C6: CC Common Cathode | D6: 0.56 Inch Red 1BIT | E6: LED Merah Display Jam Digital Nilai Sensor | F6: 7-Segment Katoda 0,56" Inci 0.56" 0.56inch 1 BIT | G6: BisaElektronika - BisaSegment | H6: 3 | I6: #ITBisa #BisaElektronika #BisaSegment #7Segment #Segment #CA #CC #Anode #Cathode #0.56 #LED #1BIT #Red #Arduino #Counter #Digital #IC #Mikrokontroler #Timer #Clock | J6: 20 | K6: ITBisa - Seven 7 Segment CC Common Cathode 0.56 Inch Red 1BIT LED Merah Display Jam Digital Nilai Sensor 7-Segment Katoda 0,56" Inci 0.56" 0.56inch 1 BIT | L6: ITBisa - Seven 7 Segment CC Common Cathode 0.56 Inch Red 1BIT LED Mera | M6: ITBisa - Seven 7 Segment CC Common Cathode 0.56 Inch Red 1BIT LED Merah Display Jam Digital Nilai Sensor 7-Segment Katoda 0,56" Inci 0.56" 0.56inch 1 | N6: ITBisa - Seven 7 Segment CC Common Cathode 0.56 Inch Red 1BIT LED Merah Display Jam Digital Nilai Sensor 7-Segment Katoda 0,56" Inci 0.56" 0.56inch 1 BIT
A7: ITBISA-7SEGMENT-CATHODE-RED-1.00-1BIT | B7: Seven 7 Segment | C7: CC Common Cathode | D7: 1 Inch Red 1BIT | E7: LED Merah Display Jam Digital Nilai Sensor | F7: 7-Segment Katoda 1" Inch 1inch BIT | G7: BisaElektronika - BisaSegment | H7: 3 | K7: ITBisa - Seven 7 Segment CC Common Cathode 1 Inch Red 1BIT LED Merah Display Jam Digital Nilai Sensor 7-Segment Katoda 1" Inch 1inch BIT | L7: ITBisa - Seven 7 Segment CC Common Cathode 1 Inch Red 1BIT LED Merah D | M7: ITBisa - Seven 7 Segment CC Common Cathode 1 Inch Red 1BIT LED Merah Display Jam Digital Nilai Sensor 7-Segment Katoda 1" Inch 1inch BIT | N7: ITBisa - Seven 7 Segment CC Common Cathode 1 Inch Red 1BIT LED Merah Display Jam Digital Nilai Sensor 7-Segment Katoda 1" Inch 1inch BIT
A8: ITBISA-7SEGMENT-CATHODE-RED-1.20-1BIT | B8: Seven 7 Segment | C8: CC Common Cathode | D8: 1.2 Inch Red 1BIT | E8: LED Merah Display Jam Digital Nilai Sensor | F8: 7-Segment Katoda 1,2" Inci 1.2" 1.2inch 1 BIT | G8: BisaElektronika - BisaSegment | H8: 3 | I8: #ITBisa #BisaElektronika #BisaSegment #7Segment #Segment #CA #CC #Anode #Cathode #0.56 #LED #1BIT #Red #Arduino #Counter #Digital #IC #Mikrokontroler #Timer #Clock | J8: 20 | K8: ITBisa - Seven 7 Segment CC Common Cathode 1.2 Inch Red 1BIT LED Merah Display Jam Digital Nilai Sensor 7-Segment Katoda 1,2" Inci 1.2" 1.2inch 1 BIT | L8: ITBisa - Seven 7 Segment CC Common Cathode 1.2 Inch Red 1BIT LED Merah | M8: ITBisa - Seven 7 Segment CC Common Cathode 1.2 Inch Red 1BIT LED Merah Display Jam Digital Nilai Sensor 7-Segment Katoda 1,2" Inci 1.2" 1.2inch 1 BIT | N8: ITBisa - Seven 7 Segment CC Common Cathode 1.2 Inch Red 1BIT LED Merah Display Jam Digital Nilai Sensor 7-Segment Katoda 1,2" Inci 1.2" 1.2inch 1 BIT
A9: ITBISA-7SEGMENT-CATHODE-RED-2.30-1BIT
A10: ITBISA-ABC-BATERAI-9V-ALKALINE
A11: ITBISA-ABC-BATERAI-9V-POWER
A12: ITBISA-ABC-BATERAI-AA-ALKALINE
A13: ITBISA-ABC-BATERAI-AAA-ALKALINE
A14: ITBISA-ABC-BATERAI-D-ALKALINE
A15: ITBISA-ABC-BATERAI-D-BIRU | B15: Baterai ABC | C15: Standar 1,5 V | D15: Size D Biru | F15: Batre Biasa 1,5V 1.5V 1.5 Volt Ukuran D Warna Blue | G15: BisaOspek | H15: 100 | I15: #ITBisa #BisaOspek #BisaBaterai #Ospek #Baterai #ABC #D #Size #1.5V #Volt #Senter #Big #Jumbo #Power #Alkaline #Carbon #Zinc #Karbon #Galon #Jumbo | J15: 20 | K15: ITBisa - Baterai ABC Standar 1,5 V Size D Biru Batre Biasa 1,5V 1.5V 1.5 Volt Ukuran D Warna Blue | L15: ITBisa - Baterai ABC Standar 1,5 V Size D Biru Batre Biasa 1,5V 1.5V 1 | M15: ITBisa - Baterai ABC Standar 1,5 V Size D Biru Batre Biasa 1,5V 1.5V 1.5 Volt Ukuran D Warna Blue | N15: ITBisa - Baterai ABC Standar 1,5 V Size D Biru Batre Biasa 1,5V 1.5V 1.5 Volt Ukuran D Warna Blue | O15: https://www.bukalapak.com/p/elektronik/komponen-elektronik/163beu6-jual-itbisa-40pcs-kabel-jumper-10-cm-male-to-female-m-f-2-54-mm-merk-dupont-arduino-breadboard-40-pcs-buah-mf-m-f-pin-2-54mm-10cm-cable | P15: https://www.tokopedia.com/itbisa/itbisa-40pcs-kabel-jumper-10-cm-male-to-female-m-f-2-54-mm-mf-10cm | Q15: https://shopee.co.id/product/80492423/2291036855/
A16: ITBISA-ABC-BATERAI-D-POWER | B16: Baterai ABC Size D | C16: Super Power Heavy Duty DR20P | D16: 1.5V Jumbo Carbon Zinc Hitam | E16: Senter Pompa Galon | F16: Batre Jumbo Karbon Tipe D R20P Besar 1,5V 1.5V 1.5 Volt Type Ukuran D Warna Black | G16: BisaOspek | H16: 100 | I16: #ITBisa #BisaOspek #BisaBaterai #Ospek #Baterai #ABC #D #Size #1.5V #Volt #Senter #Big #Jumbo #Power #Alkaline #Carbon #Zinc #Karbon #Galon #Jumbo | J16: 20 | K16: ITBisa - Baterai ABC Size D Super Power Heavy Duty DR20P 1.5V Jumbo Carbon Zinc Hitam Senter Pompa Galon Batre Jumbo Karbon Tipe D R20P Besar 1,5V 1.5V 1.5 Volt Type Ukuran D Warna Black | L16: ITBisa - Baterai ABC Size D Super Power Heavy Duty DR20P 1.5V Jumbo Ca | M16: ITBisa - Baterai ABC Size D Super Power Heavy Duty DR20P 1.5V Jumbo Carbon Zinc Hitam Senter Pompa Galon Batre Jumbo Karbon Tipe D R20P Besar 1,5V 1.5 | N16: ITBisa - Baterai ABC Size D Super Power Heavy Duty DR20P 1.5V Jumbo Carbon Zinc Hitam Senter Pompa Galon Batre Jumbo Karbon Tipe D R20P Besar 1,5V 1.5V 1.5 Volt Type Ukuran D Warna Black | O16: https://www.bukalapak.com/p/elektronik/komponen-elektronik/1b2qbb9-jual-itbisa-transistor-bjt-npn-2n2222a-h331-to92-0-6a-30v-penguat-switch-transistors-2n2222-2n-2222-a-to-92-h-331-0-6-op-amp-switching-30-v-30volt | P16: https://www.tokopedia.com/itbisa/itbisa-transistor-bjt-npn-2n2222-a-2n2222a-h331-penguat-switch-to92 | Q16: https://shopee.co.id/product/80492423/2291143520/
A17: ITBISA-ABC-SENTER-LED-ALKALINE | B17: Senter ABC Alkaline | C17: LED Multifungsi | E17: Emergency Light | F17: Multifunction LED Lights | G17: BisaSenter | H17: 300 | I17: #ITBisa #BisaOspek #BisaSenter #Ospek #Baterai #ABC #AAA | J17: 7 | K17: ITBisa - Senter ABC Alkaline LED Multifungsi Emergency Light Multifunction LED Lights | L17: ITBisa - Senter ABC Alkaline LED Multifungsi Emergency Light Multifunc | M17: ITBisa - Senter ABC Alkaline LED Multifungsi Emergency Light Multifunction LED Lights | N17: ITBisa - Senter ABC Alkaline LED Multifungsi Emergency Light Multifunction LED Lights
A18: ITBISA-ARDUINO-UNO-R3-328P-SMD | B18: Arduino | C18: UNO R3 CH340G SMD ATMega328P | D18: Clone Only No Cable | E18: Mikrokontroler | F18: Tanpa Kabel USB ATMega328 AT Mega Kloning Duplikat Microcontroller | G18: BisaElektronika | K18: ITBisa - Arduino UNO R3 CH340G SMD ATMega328P Clone Only No Cable Mikrokontroler Tanpa Kabel USB ATMega328 AT Mega Kloning Duplikat Microcontroller | L18: ITBisa - Arduino UNO R3 CH340G SMD ATMega328P Clone Only No Cable Mikr | M18: ITBisa - Arduino UNO R3 CH340G SMD ATMega328P Clone Only No Cable Mikrokontroler Tanpa Kabel USB ATMega328 AT Mega Kloning Duplikat Microcontroller | N18: ITBisa - Arduino UNO R3 CH340G SMD ATMega328P Clone Only No Cable Mikrokontroler Tanpa Kabel USB ATMega328 AT Mega Kloning Duplikat Microcontroller
A19: ITBISA-ARDUINO-UNO-R3-CLONE-CABLE30CM | B19: Arduino | C19: UNO R3 CH340G SMD | D19: Clone Plus + USB Kabel 30CM Cable 30 CM ATMega328P | E19: Mikrokontroler | F19: ATMega328 AT Mega 328 P + Cable Kloning Duplikat Microcontroller | G19: BisaElektronika | K19: ITBisa - Arduino UNO R3 CH340G SMD Clone Plus + USB Kabel 30CM Cable 30 CM ATMega328P Mikrokontroler ATMega328 AT Mega 328 P + Cable Kloning Duplikat Microcontroller | L19: ITBisa - Arduino UNO R3 CH340G SMD Clone Plus + USB Kabel 30CM Cable 3 | M19: ITBisa - Arduino UNO R3 CH340G SMD Clone Plus + USB Kabel 30CM Cable 30 CM ATMega328P Mikrokontroler ATMega328 AT Mega 328 P + Cable Kloning Duplikat | N19: ITBisa - Arduino UNO R3 CH340G SMD Clone Plus + USB Kabel 30CM Cable 30 CM ATMega328P Mikrokontroler ATMega328 AT Mega 328 P + Cable Kloning Duplikat Microcontroller
A20: ITBISA-ARDUINO-UNO-R3-CLONE-CABLE50CM | B20: Arduino | C20: UNO R3 CH340G ATMega328P SMD | D20: Clone Plus USB Kabel 50CM | E20: Mikrokontroler | F20: ATMega328 AT Mega 328 P + Cable 50 cm Kloning Duplikat Microcontroller | G20: BisaElektronika | K20: ITBisa - Arduino UNO R3 CH340G ATMega328P SMD Clone Plus USB Kabel 50CM Mikrokontroler ATMega328 AT Mega 328 P + Cable 50 cm Kloning Duplikat Microcontroller | L20: ITBisa - Arduino UNO R3 CH340G ATMega328P SMD Clone Plus USB Kabel 50C | M20: ITBisa - Arduino UNO R3 CH340G ATMega328P SMD Clone Plus USB Kabel 50CM Mikrokontroler ATMega328 AT Mega 328 P + Cable 50 cm Kloning Duplikat Microcon | N20: ITBisa - Arduino UNO R3 CH340G ATMega328P SMD Clone Plus USB Kabel 50CM Mikrokontroler ATMega328 AT Mega 328 P + Cable 50 cm Kloning Duplikat Microcontroller
A21: ITBISA-BLUETOOTH-MODULE-HC05
A22: ITBISA-BREADBOARD-830HOLE-MB102
A23: ITBISA-BUBBLE-WRAP | O23: https://www.bukalapak.com/p/elektronik/komponen-elektronik/1p5d40c-jual-itbisa-40pcs-kabel-jumper-10-cm-female-to-female-f-f-2-54-mm-merk-dupont-arduino-breadboard-40-pcs-buah-ff-f-f-pin-2-54mm-10cm-cable | P23: https://www.tokopedia.com/itbisa/itbisa-40pcs-kabel-jumper-10-cm-female-to-female-f-f-2-54-mm-ff-10cm | Q23: https://shopee.co.id/product/80492423/2287703561/
A24: ITBISA-BUKAEMAS | O24: https://www.bukalapak.com/p/elektronik/komponen-elektronik/2aposh9-jual-itbisa-socket-ic-dip-8-2x4-narrow-soket-integrated-circuit-8-pin-kaki-lubang-datar-dip8-8dip | P24: https://tokopedia.com/itbisa/itbisa-socket-ic-dip-8-2x4-narrow-soket-dip8-8dip-8-dip-pin-kaki | Q24: https://shopee.co.id/product/80492423/2287659492/
A25: ITBISA-BUKAREKSA-BAHANA-MES-SYARIAH
A26: ITBISA-BUKAREKSA-CIMB-PRINCIPAL-PASAR-UANG
A27: ITBISA-BUKAREKSA-CIPTA-SYARIAH-BALANCE
A28: ITBISA-BUKAREKSA-MANDIRI-INVESTA-DANA-SYARIAH | O28: https://www.bukalapak.com/p/elektronik/komponen-elektronik/3ge7cl1-jual-itbisa-socket-ic-dip16-2x8-narrow-dip-16-pin-16p-soket-dip-16-2-54mm-2-54-mm-dudukan-16-lubang-16-dip-integrated-integrate-circuit-2-x-8-8x2-8-x-2 | P28: https://tokopedia.com/itbisa/itbisa-socket-ic-dip16-2x8-narrow-dip-16-pin-16p-soket-dip-16-2-54mm
A29: ITBISA-BUKAREKSA-MANDIRI-INVESTA-PASAR-UANG | O29: https://www.bukalapak.com/p/elektronik/komponen-elektronik/3t18497-jual-itbisa-40pcs-kabel-jumper-20-cm-male-to-male-m-m-mm-m-m-2-54mm-arduino-breadboard-40-pcs-20cm-buah-pin-2-54-mm-wire-cable-rainbow-pelangi-sensor | P29: https://tokopedia.com/itbisa/itbisa-40pcs-kabel-jumper-20-cm-male-to-male-m-m-2-54-mm-mm-m-m-20cm | Q29: https://shopee.co.id/product/80492423/4855244491/
A30: ITBISA-BUKAREKSA-SUCORINVEST-SHARIA-EQUITY-FUND | O30: https://www.bukalapak.com/p/elektronik/komponen-elektronik/3t187p8-jual-itbisa-40pcs-kabel-jumper-20-cm-female-to-female-f-f-ff-f-f-2-54mm-arduino-breadboard-40-pcs-20cm-buah-pin-2-54-mm-wire-cable-rainbow-pelangi-sensor | P30: https://www.tokopedia.com/itbisa/itbisa-40pcs-kabel-jumper-20-cm-female-to-female-f-f-2-54-mm-ff-20cm | Q30: https://shopee.co.id/product/80492423/5655241072/
A31: ITBISA-BUKAREKSA-SYARIAH-MANDIRI-PASAR-UANG | O31: https://www.bukalapak.com/p/elektronik/komponen-elektronik/vbuzpu-jual-itbisa-40pcs-kabel-jumper-10-cm-male-to-male-m-m-2-54-mm-merk-dupont-arduino-breadboard-40-pcs-buah-mm-m-m-pin-2-54mm-10cm-cable | P31: https://www.tokopedia.com/itbisa/itbisa-40pcs-kabel-jumper-10-cm-male-to-male-m-m-2-54-mm-mm-m-m-10cm | Q31: https://shopee.co.id/product/80492423/2291050648/
A32: ITBISA-BUZZER-ACTIVE-5V
A33: ITBISA-CHIP-ESP32-WROOM
A34: ITBISA-CHIP-ESP32-WROOM-ANTENNA
A35: ITBISA-CHIP-ESP8266-ESP12F
A36: ITBISA-CORSAIR-VENGEANCE-K66
A37: ITBISA-DC-TO-DC-STEPDOWN-LM2596 | P37: https://www.tokopedia.com/itbisa/itbisa-seven-7-segment-ca-common-anode-0-56-inch-red-1bit-led-merah
A38: ITBISA-DC-TO-DC-STEPDOWN-XL4005
A39: ITBISA-DC-TO-DC-STEPDOWN-XL4015
A40: ITBISA-DC-TO-DC-STEPUP-XL6009 | P40: https://tokopedia.com/itbisa/itbisa-baterai-abc-super-power-1-5-v-volt-size-d-hitam-carbon-zinc
...

Sheet BisaEtalase
A1: Level 1 | B1: Level 2
A2: Elektronika
B3: IC
B4: Induktor
B5: Kabel
B6: Kapasitor
B7: Lampu
B8: Mikrokontroler
B9: PCB
B10: Resistor
B11: Segment
B12: Socket
B13: Transistor
A14: Ospek
B15: Lampu
B16: Sarung Tangan
B17: Senter
B18: Syal
B19: Baterai

Sheet BisaPerlengkapan
A1: Tanggal Beli | B1: Jenis Transaksi Debit | C1: Jenis Transaksi Kredit | D1: Nominal | E1: Keterangan
A3: 43314.787 | B3: Perlengkapan Tape Cutter | C3: Kas ITBisa | D3: 38800 | E3: Tape Cutter Borma (Mahal?)
A4: 43316 | B4: Perlengkapan Bubble Wrap | C4: Kas ITBisa | D4: =135000+19000 -> 154000 | E4: Bubble Wrap 50cmx1.25m
A5: 43316.631 | B5: Perlengkapan Baterai | C5: Kas ITBisa | D5: 17100 | E5: Aji membeli Baterai ABC Super Power size D, Testing Baterai ABC buat senter
A6: 43422 | B6: Perlengkapan Selotip | C6: Kas ITBisa | D6: 15000 | E6: Selotip Cokelat
A7: 43440 | B7: Perlengkapan Plastik Klip | C7: Kas ITBisa | D7: =1*12000 + 6000 -> 18000 | E7: 1 x 1000 x https://www.tokopedia.com/dwi-jaya/kantong-plastik-klip-3-cm-x-5-cm-isi-1000-pcs
A8: 43477.58 | B8: Perlengkapan Plastik Klip | C8: Kas ITBisa | D8: =8*4300 + 10000 -> 44400 | E8: 800 x https://www.tokopedia.com/jayaplastik/plastik-klip-8x12-cm-termurah
A9: 43516 | B9: Perlengkapan Keresek | C9: Kas ITBisa | D9: 7500 | E9: Beli Keresek/Plastik Hitam
A10: 43516 | B10: Perlengkapan Selotip | C10: Kas ITBisa | D10: 7000 | E10: Beli Solasi/Selotip Bening
A11: 43522.943 | B11: Perlengkapan Bubble Wrap | C11: Kas ITBisa | D11: =129000+36000 -> 165000 | E11: Bubble Wrap 50cmx1.25m
A12: 43543.737 | B12: Perlengkapan Lainnya | C12: Kas ITBisa | D12: 50000 | E12: Aji membeli Arduino dari ITBisa
A13: 43554 | B13: Perlengkapan Selotip | C13: Kas ITBisa | D13: =4*6500 + 5*5000 + 8500 - 8500 -> 51000 | E13: Lakban Bening
A14: 43584.587 | B14: Perlengkapan Gunting | C14: Kas ITBisa | D14: =13000*2 + 7000 -> 33000 | E14: 2x Gunting De Xian
A15: 43584.588 | B15: Perlengkapan Label | C15: Kas ITBisa | D15: =3600*2 + 5000 -> 12200 | E15: 2x1960 Label 113
