Workbook

Sheet Beranda
A1: Link | B1: Fungsi
A2: =HYPERLINK("https://docs.google.com/spreadsheets/d/1ESni1h-9NP1dVdHaEILuc6WWv_P8-mWX3jXPRX9GysM/edit#gid=1979551602","BisaStok") -> BisaStok | B2: Menuliskan pembelian stok dari Kas ITBisa
A3: =HYPERLINK("https://docs.google.com/spreadsheets/d/1ESni1h-9NP1dVdHaEILuc6WWv_P8-mWX3jXPRX9GysM/edit#gid=533652570","BisaPerlengkapan") -> BisaPerlengkapan | B3: Menuliskan perlengkapan yang berhubungan dengan penjualan
A4: =HYPERLINK("https://docs.google.com/spreadsheets/d/1ESni1h-9NP1dVdHaEILuc6WWv_P8-mWX3jXPRX9GysM/edit#gid=1164177046","BisaHitungImpor") -> BisaHitungImpor
A5: =HYPERLINK("https://docs.google.com/spreadsheets/d/1ESni1h-9NP1dVdHaEILuc6WWv_P8-mWX3jXPRX9GysM/edit#gid=90517666","BisaEksporBisaJual") -> BisaEksporBisaJual
A6: =HYPERLINK("https://docs.google.com/spreadsheets/d/1ESni1h-9NP1dVdHaEILuc6WWv_P8-mWX3jXPRX9GysM/edit#gid=171163769","BisaHilang") -> BisaHilang
A7: =HYPERLINK("https://docs.google.com/spreadsheets/d/1ESni1h-9NP1dVdHaEILuc6WWv_P8-mWX3jXPRX9GysM/edit#gid=1152745648","BisaJualBukalapak") -> BisaJualBukalapak | B7: Menuliskan semua transaksi barang dari Bukalapak
A8: =HYPERLINK("https://docs.google.com/spreadsheets/d/1ESni1h-9NP1dVdHaEILuc6WWv_P8-mWX3jXPRX9GysM/edit#gid=1873910816","BisaJualTokopedia") -> BisaJualTokopedia | B8: Menuliskan semua transaksi barang dari Tokopedia
A9: =HYPERLINK("https://docs.google.com/spreadsheets/d/1ESni1h-9NP1dVdHaEILuc6WWv_P8-mWX3jXPRX9GysM/edit#gid=1921632670","BisaJualBliBli") -> BisaJualBliBli
A10: =HYPERLINK("https://docs.google.com/spreadsheets/d/1ESni1h-9NP1dVdHaEILuc6WWv_P8-mWX3jXPRX9GysM/edit#gid=1461742550","BisaJualWeb") -> BisaJualWeb
A11: =HYPERLINK("https://docs.google.com/spreadsheets/d/1ESni1h-9NP1dVdHaEILuc6WWv_P8-mWX3jXPRX9GysM/edit#gid=526519451","BisaJualCOD") -> BisaJualCOD
A12: =HYPERLINK("https://docs.google.com/spreadsheets/d/1ESni1h-9NP1dVdHaEILuc6WWv_P8-mWX3jXPRX9GysM/edit#gid=716139622","BisaSEO") -> BisaSEO

Sheet BisaStok
D1: Pengiriman | F1: Pembelian | J1: Data Invoice | R1: USD | X1: Rp | AD1: Penjualan
A2: SKU | B2: Tanggal Bayar | C2: Tanggal Sampai | D2: Alamat Pengiriman | E2: Luar Negeri? | F2: Toko | G2: URL Beli | H2: Keterangan Pembelian | I2: Score (0 - 5) | J2: Banyak Lot | K2: Pcs per Lot | L2: HPP per Lot (USD) | M2: Ongkos Kirim (USD) | N2: Diskon Barang (USD) | O2: Diskon Ongkos Kirim (USD) | P2: Konversi USD ke Rupiah | Q2: {={"Banyak Barang (Buah)";IF(J3:J263*K3:K263=0,,J3:J263*K3:K263)}} -> Banyak Barang (Buah) | R2: {={"Total Harga Lot (USD)";IF(J3:J263*L3:L263=0,,J3:J263*L3:L263)}} -> Total Harga Lot (USD) | S2: {={"Ongkos Kirim (USD)";IF(M3:M263=0,,M3:M263)}} -> Ongkos Kirim (USD) | T2: {={"Diskon Barang (USD)";IF(N3:N263=0,,N3:N263)}} -> Diskon Barang (USD) | U2: {={"Diskon Ongkos Kirim (USD)";IF(O3:O263=0,,O3:O263)}} -> Diskon Ongkos Kirim (USD) | V2: {={"Total HPP (USD)";IF(R3:R263+M3:M263-N3:N263-O3:O263=0,,R3:R263+M3:M263-N3:N263-O3:O263)}} -> Total HPP (USD) | W2: {={"HPP per Buah (USD)";IF(V3:V263=0,,V3:V263/Q3:Q263)}} -> HPP per Buah (USD) | X2: {={"Total Harga Lot (Rp)";IF(R3:R263=0,,R3:R263*P3:P263)}} -> Total Harga Lot (Rp) | Y2: {={"Ongkos Kirim (Rp)";IF(S3:S263*$P$3:$P263=0,,S3:S263*$P$3:$P263)}} -> Ongkos Kirim (Rp) | Z2: {={"Diskon Barang (Rp)";IF(T3:T263*$P$3:$P263=0,,T3:T263*$P$3:$P263)}} -> Diskon Barang (Rp) | AA2: {={"Diskon Ongkos Kirim (Rp)";IF(U3:U263*$P$3:$P263=0,,U3:U263*$P$3:$P263)}} -> Diskon Ongkos Kirim (Rp) | AB2: {={"Total HPP (Rp)";IF(V3:V263*$P$3:$P263=0,,V3:V263*$P$3:$P263)}} -> Total HPP (Rp) | AC2: {={"HPP per Buah (Rp)";IF(AB3:AB263=0,,AB3:AB263/Q3:Q263)}} -> HPP per Buah (Rp) | AD2: Harga Online/ Dropshipper (Rp) | AE2: Harga Offline (Rp) | AF2: Lain-Lain
A4: ITBISA-IC-LM741CN-DIP8 | B4: 43590.408 | C4: 43596 | D4: KYAI KONTONG | E4: FALSE | F4: Migrasi - Shopee | G4: https://shopee.co.id/20pcs-IC-lm741c-lm741cn-DIP-8Pin-UA741CN-Amp-LM741-Amp-i.77214376.1434513222 | H4: Shopee Furqonajiy 19050510476HUJK ( - ) Mahal ( + ) Untuk Testing Darurat Pesan (?) setiap 10 buah diberi strefoam | I4: 5 | J4: 21 | K4: 1 | L4: 1291.1 | M4: 0 | N4: 0 | O4: 0 | P4: 1 | Q4: 21 | R4: 27113.1 | V4: 27113.1 | W4: 1291.1 | X4: 27113.1 | AB4: 27113.1 | AC4: 1291.1
A5: ITBISA-RESISTOR-470K-1/4W | B5: 44032 | C5: 44039 | D5: KYAI KONTONG | E5: FALSE | F5: Migrasi - Tokopedia | G5: https://www.tokopedia.com/multigshop/1000-pcs-resistor-470k-1-4-watt | H5: Tokopedia Furqonajiy | I5: 5 | J5: 980 | K5: 1 | L5: 22.43 | M5: 0 | N5: 0 | O5: 0 | P5: 1 | Q5: 980 | R5: 21981.4 | V5: 21981.4 | W5: 22.43 | X5: 21981.4 | AB5: 21981.4 | AC5: 22.43
A6: ITBISA-RESISTOR-56K-1/4W | B6: 44039 | C6: 44041 | D6: KYAI KONTONG | E6: FALSE | F6: Migrasi - Tokopedia | G6: https://www.tokopedia.com/smartmm/resistor-1-4w-56k-1000biji | H6: Tokopedia Furqonajiy | I6: 5 | J6: 650 | K6: 1 | L6: 20 | M6: 0 | N6: 0 | O6: 0 | P6: 1 | Q6: 650 | R6: 13000 | V6: 13000 | W6: 20 | X6: 13000 | AB6: 13000 | AC6: 20
A7: ITBISA-RAPID-BOHLAM-E10-3.8V-SCREW | B7: 44871 | C7: 44873 | D7: KYAI KONTONG | E7: FALSE | F7: Migrasi - Tokopedia | G7: https://www.tokopedia.com/evelinel/bohlam-e-10-bola-lampu-senter-drat-e10-rapid-isi-50-pcs-kotak?utm_source=whatsapp&utm_medium=share&utm_campaign=PDP-2644979-5342447705-301022-contextual_image | H7: Tokopedia Furqonajiy | I7: 5 | J7: 824 | K7: 1 | L7: 559.96 | M7: 0 | N7: 0 | O7: 0 | P7: 1 | Q7: 824 | R7: 461407.04 | V7: 461407.04 | W7: 559.96 | X7: 461407.04 | AB7: 461407.04 | AC7: 559.96
A8: ITBISA-7SEGMENT-CATHODE-RED-0.56-1BIT | B8: 45013 | C8: 45061 | D8: KYAI KONTONG | E8: FALSE | F8: Migrasi - Jasa Impor Tiongkok | G8: Jasa Impor Tiongkok | I8: 5 | J8: 2866 | K8: 1 | L8: 731 | M8: 0 | N8: 0 | O8: 0 | P8: 1 | Q8: 2866 | R8: 2095046 | V8: 2095046 | W8: 731 | X8: 2095046 | AB8: 2095046 | AC8: 731
A9: ITBISA-IC-UA741CN-DIP8 | B9: 45085 | C9: 45129 | D9: KYAI KONTONG | E9: FALSE | F9: Migrasi - Jasa Impor Tiongkok | G9: Jasa Impor Tiongkok | H9: Tokopedia Furqonajiy 1x Invoice | I9: 5 | J9: 5007 | K9: 1 | L9: 572 | M9: 0 | N9: 0 | O9: 0 | P9: 1 | Q9: 5007 | R9: 2864004 | V9: 2864004 | W9: 572 | X9: 2864004 | AB9: 2864004 | AC9: 572
A10: ITBISA-7SEGMENT-CATHODE-RED-1.20-1BIT | B10: 45202.354 | C10: 45232.639 | D10: KYAI KONTONG | E10: FALSE | F10: Migrasi - Jasa Impor Tiongkok | G10: Jasa Impor Tiongkok | I10: 5 | J10: 404 | K10: 1 | L10: 2756 | M10: 0 | N10: 0 | O10: 0 | P10: 1 | Q10: 404 | R10: 1113424 | V10: 1113424 | W10: 2756 | X10: 1113424 | AB10: 1113424 | AC10: 2756
A11: ITBISA-7SEGMENT-CATHODE-RED-2.30-1BIT | B11: 45265.69 | C11: 45341.64 | D11: KYAI KONTONG | E11: TRUE | F11: Migrasi - Ocistok/Martkita | G11: Ocistok | I11: 5 | J11: 60 | K11: 1 | L11: 6028 | M11: 0 | N11: 0 | O11: 0 | P11: 1 | Q11: 60 | R11: 361680 | V11: 361680 | W11: 6028 | X11: 361680 | AB11: 361680 | AC11: 6028
A12: ITBISA-TIGERHEAD-SENTER-KUNING-FT300 | B12: 45336.46 | C12: 45313.25 | D12: KYAI KONTONG | E12: FALSE | F12: Migrasi - Shopee | G12: Shopee Aji | H12: Shopee Aji | I12: 5 | J12: 1 | K12: 1 | L12: 10607.58 | M12: 0 | N12: 0 | O12: 0 | P12: 1 | Q12: 1 | R12: 10607.58 | V12: 10607.58 | W12: 10607.58 | X12: 10607.58 | AB12: 10607.58 | AC12: 10607.58
A13: ITBISA-LED-MAX7219-4IN1-GAP | B13: 45361.603 | C13: 45365.484 | D13: KYAI KONTONG | E13: FALSE | F13: Migrasi - Art Techno | G13: Art Techno | H13: Art Techno | I13: 5 | J13: 5 | K13: 1 | L13: 36500 | M13: 0 | N13: 0 | O13: 0 | P13: 1 | Q13: 5 | R13: 182500 | V13: 182500 | W13: 36500 | X13: 182500 | AB13: 182500 | AC13: 36500
A14: ITBISA-7SEGMENT-ANODE-RED-1.00-1BIT | B14: 45374.679 | C14: 45477.917 | D14: KYAI KONTONG | E14: TRUE | F14: Migrasi - Ocistok/Martkita | G14: https://detail.1688.com/offer/678795685587.html | H14: MKT-63258 / 187963 (0.85 RMB) | I14: 5 | J14: 2159 | K14: 1 | L14: 2000 | M14: 0 | N14: 0 | O14: 0 | P14: 1 | Q14: 2159 | R14: 4318000 | V14: 4318000 | W14: 2000 | X14: 4318000 | AB14: 4318000 | AC14: 2000
A15: ITBISA-RESISTOR-33K-1/4W | B15: 45381.201 | C15: 45384.568 | D15: KYAI KONTONG | E15: FALSE | F15: Migrasi - Shopee | G15: Shopee Aji GTGD | H15: Shopee Aji GTGD | I15: 5 | J15: 1760 | K15: 1 | L15: 21.75 | M15: 0 | N15: 0 | O15: 0 | P15: 1 | Q15: 1760 | R15: 38280 | V15: 38280 | W15: 21.75 | X15: 38280 | AB15: 38280 | AC15: 21.75
A16: ITBISA-NODEMCU-V3-CH340G-ESP8266-MICRO | B16: 45409.658 | C16: 45411.659 | D16: KYAI KONTONG | E16: FALSE | F16: Migrasi - Tokopedia | G16: Tokopedia Hendang | H16: Tokopedia Hendang | I16: 5 | J16: 310 | K16: 1 | L16: 23261.03 | M16: 0 | N16: 0 | O16: 0 | P16: 1 | Q16: 310 | R16: 7210919.3 | V16: 7210919.3 | W16: 23261.03 | X16: 7210919.3 | AB16: 7210919.3 | AC16: 23261.03
A17: ITBISA-RAPID-BOHLAM-E10-2.5V-SCREW | B17: 45411.511 | C17: 45414.417 | D17: KYAI KONTONG | E17: FALSE | F17: Migrasi - Shopee | G17: Shopee Aji 5E6M | H17: Shopee Aji 5E6M | I17: 5 | J17: 1224 | K17: 1 | L17: 640.67 | M17: 0 | N17: 0 | O17: 0 | P17: 1 | Q17: 1224 | R17: 784180.08 | V17: 784180.08 | W17: 640.67 | X17: 784180.08 | AB17: 784180.08 | AC17: 640.67
A18: ITBISA-ABC-BATERAI-D-POWER | B18: 45414.907 | C18: 45415.655 | D18: KYAI KONTONG | E18: FALSE | F18: Migrasi - Tokopedia | G18: SmartBrain Tokopedia | H18: SmartBrain Tokopedia | I18: 5 | J18: 1 | K18: 1 | L18: 5166.67 | M18: 0 | N18: 0 | O18: 0 | P18: 1 | Q18: 1 | R18: 5166.67 | V18: 5166.67 | W18: 5166.67 | X18: 5166.67 | AB18: 5166.67 | AC18: 5166.67
A19: ITBISA-SENSOR-SUHU-DHT11 | B19: 45417.981 | C19: 45421.604 | D19: KYAI KONTONG | E19: FALSE | F19: Migrasi - Shopee | G19: Shopee Anggi VMGV | H19: Shopee Anggi VMGV | I19: 5 | J19: 36 | K19: 1 | L19: 8283.86 | M19: 0 | N19: 0 | O19: 0 | P19: 1 | Q19: 36 | R19: 298218.96 | V19: 298218.96 | W19: 8283.86 | X19: 298218.96 | AB19: 298218.96 | AC19: 8283.86
A20: ITBISA-RESISTOR-4K7-1/4W | B20: 45421.205 | C20: 45423.626 | D20: KYAI KONTONG | E20: FALSE | F20: Migrasi - Shopee | G20: STARVIS CCTV | H20: Shopee Aji QK45 | I20: 5 | J20: 2873 | K20: 1 | L20: 21.7 | M20: 0 | N20: 0 | O20: 0 | P20: 1 | Q20: 2873 | R20: 62344.1 | V20: 62344.1 | W20: 21.7 | X20: 62344.1 | AB20: 62344.1 | AC20: 21.7
A21: ITBISA-IC-ULN2803APG-DIP18 | B21: 45426.593 | C21: 45493.667 | D21: KYAI KONTONG | E21: TRUE | F21: Migrasi - Ocistok/Martkita | G21: Ocistok | H21: Ocistok 205883 | I21: 5 | J21: 1321 | K21: 1 | L21: 1018 | M21: 0 | N21: 0 | O21: 0 | P21: 1 | Q21: 1321 | R21: 1344778 | V21: 1344778 | W21: 1018 | X21: 1344778 | AB21: 1344778 | AC21: 1018
A22: ITBISA-IC-L7805CV-TO220 | B22: 45426.999 | C22: 45429.457 | D22: KYAI KONTONG | E22: FALSE | F22: Migrasi - Shopee | G22: SukiTech | H22: Shopee Aji F1PM | I22: 5 | J22: 4531 | K22: 1 | L22: 1140.72 | M22: 0 | N22: 0 | O22: 0 | P22: 1 | Q22: 4531 | R22: 5168602.3 | V22: 5168602.3 | W22: 1140.72 | X22: 5168602.3 | AB22: 5168602.3 | AC22: 1140.72
A23: ITBISA-IC-L7812CV-TO220 | B23: 45452.715 | C23: 45456.594 | D23: KYAI KONTONG | E23: FALSE | F23: Migrasi - Shopee | G23: GT Electronik | H23: Shopee Aji F9QB | I23: 5 | J23: 1083 | K23: 1 | L23: 1057 | M23: 0 | N23: 0 | O23: 0 | P23: 1 | Q23: 1083 | R23: 1144731 | V23: 1144731 | W23: 1057 | X23: 1144731 | AB23: 1144731 | AC23: 1057
... A132: ITBISA-WEMOS-D1-MINI-ESP8266 | B132: 46003.633 | C132: 46004.816 | D132: KYAI KONTONG | E132: FALSE | F132: Migrasi - Shopee | G132: IndoTechno New | H132: Shopee Aji VFX9 | I132: 5 | J132: 120 | K132: 1 | L132: 20791.2 | M132: 0 | N132: 0 | O132: 0 | P132: 1 | Q132: 120 | R132: 2494944 | V132: 2494944 | W132: 20791.2 | X132: 2494944 | AB132: 2494944 | AC132: 20791.2
A133: ITBISA-BUBBLE-WRAP | B133: 46022.417 | C133: 46022.458 | D133: KYAI KONTONG | E133: FALSE | F133: Migrasi - Migrasi | G133: Migrasi | I133: 5 | J133: 70 | K133: 1 | M133: 0 | N133: 0 | O133: 0 | P133: 1 | Q133: 70
A134: ITBISA-ABC-BATERAI-9V-POWER | B134: 46024.659 | C134: 46036.749 | D134: KYAI KONTONG | E134: FALSE | F134: PT Arta Boga | G134: PT Arta Boga | H134: PT Arta Boga | I134: 5 | J134: 1 | K134: 144 | L134: =(1614384)/P134 -> 1614384 | M134: 9 | N134: 9 | O134: 9 | P134: 1 | Q134: 144 | R134: 1614384 | S134: 9 | T134: 9 | U134: 9 | V134: 1614375 | W134: 11210.938 | X134: 1614384 | Y134: 9 | Z134: 9 | AA134: 9 | AB134: 1614375 | AC134: 11210.938
A135: ITBISA-JACK-DC-005-FEMALE | B135: 46041.688 | C135: 46047.598 | D135: KERTASARI CIAMIS | E135: FALSE | F135: Shopee | G135: Golden Dream Official Shop | H135: Shopee Aji 47MX | I135: 5 | J135: 99 | K135: 1 | L135: =(380)/P135 -> 380 | M135: =(2000)/P135 -> 2000 | N135: =(15000)/P135 -> 15000 | O135: 0 | P135: 1 | Q135: 99 | R135: 37620 | S135: 2000 | T135: 15000 | V135: 24620 | W135: 248.68687 | X135: 37620 | Y135: 2000 | Z135: 15000 | AB135: 24620 | AC135: 248.68687
A136: ITBISA-ABC-BATERAI-AA-ALKALINE | B136: 46044.458 | C136: 46047.371 | D136: KERTASARI CIAMIS | E136: FALSE | F136: Shopee | G136: Awalia Store | H136: Shopee Aji V92Q | I136: 5 | J136: 5 | K136: 6 | L136: =(28950)/P136 -> 28950 | M136: =(1200)/P136 -> 1200 | N136: =(28950)/P136 -> 28950 | O136: 0 | P136: 1 | Q136: 30 | R136: 144750 | S136: 1200 | T136: 28950 | V136: 117000 | W136: 3900 | X136: 144750 | Y136: 1200 | Z136: 28950 | AB136: 117000 | AC136: 3900
A137: ITBISA-SOCKET-IC-DIP8-NARROW | B137: 46047.995 | C137: 46050.483 | D137: KYAI KONTONG | E137: FALSE | F137: Shopee | G137: ARS AUDIO 226 | H137: Shopee Aji NP55 | I137: 5 | J137: 1020 | K137: 1 | L137: =(210)/P137 -> 210 | M137: =(1200)/P137 -> 1200 | N137: =(32130)/P137 -> 32130 | O137: 0 | P137: 1 | Q137: 1020 | R137: 214200 | S137: 1200 | T137: 32130 | V137: 183270 | W137: 179.67647 | X137: 214200 | Y137: 1200 | Z137: 32130 | AB137: 183270 | AC137: 179.67647
A138: ITBISA-IC-74HC245N-DIP20 | B138: 46052.484 | C138: 46116.701 | D138: KYAI KONTONG | E138: TRUE | F138: Ocistok/Martkita | G138: https://detail.1688.com/offer/679786580432.html | H138: MKT-137391 / 319508 | I138: 5 | J138: 5000 | K138: 1 | L138: =(1435)/P138 -> 1435 | M138: =(25530)/P138 -> 25530 | N138: =(500000)*(R138/50094000) -> 71615.363 | P138: 1 | Q138: 5000 | R138: 7175000 | S138: 25530 | T138: 71615.363 | V138: 7128914.6 | W138: 1425.7829 | X138: 7175000 | Y138: 25530 | Z138: 71615.363 | AB138: 7128914.6 | AC138: 1425.7829
A139: ITBISA-RELAY-5V-4PIN-BLUE | B139: 46052.484 | C139: 46116.701 | D139: KYAI KONTONG | E139: TRUE | F139: Ocistok/Martkita | G139: https://detail.1688.com/offer/775368378784.html | H139: MKT-137392 / 319509 | I139: 5 | J139: 2000 | K139: 1 | L139: =(1781)/P139 -> 1781 | M139: =(233322)*(R139/33839000) -> 24560.211 | N139: =(500000)*(R139/50094000) -> 35553.16 | P139: 1 | Q139: 2000 | R139: 3562000 | S139: 24560.211 | T139: 35553.16 | V139: 3551007.1 | W139: 1775.5035 | X139: 3562000 | Y139: 24560.211 | Z139: 35553.16 | AB139: 3551007.1 | AC139: 1775.5035
A140: ITBISA-RELAY-12V-4PIN-BLUE | B140: 46052.484 | C140: 46116.701 | D140: KYAI KONTONG | E140: TRUE | F140: Ocistok/Martkita | G140: https://detail.1688.com/offer/775368378784.html | H140: MKT-137392 / 319509 | I140: 5 | J140: 5000 | K140: 1 | L140: =(1781)/P140 -> 1781 | M140: =(233322)*(R140/33839000) -> 61400.526 | N140: =(500000)*(R140/50094000) -> 88882.9 | P140: 1 | Q140: 5000 | R140: 8905000 | S140: 61400.526 | T140: 88882.9 | V140: 8877517.6 | W140: 1775.5035 | X140: 8905000 | Y140: 61400.526 | Z140: 88882.9 | AB140: 8877517.6 | AC140: 1775.5035
A141: ITBISA-RELAY-12V-5PIN-BLUE | B141: 46052.484 | C141: 46116.701 | D141: KYAI KONTONG | E141: TRUE | F141: Ocistok/Martkita | G141: https://detail.1688.com/offer/775368378784.html | H141: MKT-137392 / 319509 | I141: 5 | J141: 10000 | K141: 1 | L141: =(1781)/P141 -> 1781 | M141: =(233322)*(R141/33839000) -> 122801.05 | N141: =(500000)*(R141/50094000) -> 177765.8 | P141: 1 | Q141: 10000 | R141: 17810000 | S141: 122801.05 | T141: 177765.8 | V141: 17755035 | W141: 1775.5035 | X141: 17810000 | Y141: 122801.05 | Z141: 177765.8 | AB141: 17755035 | AC141: 1775.5035
A142: ITBISA-RELAY-5V-5PIN-BLUE | B142: 46052.484 | C142: 46116.701 | D142: KYAI KONTONG | E142: TRUE | F142: Ocistok/Martkita | G142: https://detail.1688.com/offer/775368378784.html | H142: MKT-137392 / 319509 | I142: 5 | J142: 2000 | K142: 1 | L142: =(1781)/P142 -> 1781 | M142: =(233322)*(R142/33839000) -> 24560.211 | N142: =(500000)*(R142/50094000) -> 35553.16 | P142: 1 | Q142: 2000 | R142: 3562000 | S142: 24560.211 | T142: 35553.16 | V142: 3551007.1 | W142: 1775.5035 | X142: 3562000 | Y142: 24560.211 | Z142: 35553.16 | AB142: 3551007.1 | AC142: 1775.5035
A143: ITBISA-IC-CD4094BM-SMD-SOP16 | B143: 46052.484 | C143: 46116.701 | D143: KYAI KONTONG | E143: TRUE | F143: Ocistok/Martkita | G143: https://detail.1688.com/offer/575196879958.html | H143: MKT-137393 / 319510 | I143: 5 | J143: 10000 | K143: 1 | L143: =(590)/P143 -> 590 | M143: =(18870)/P143 -> 18870 | N143: =(500000)*(R143/50094000) -> 58889.288 | P143: 1 | Q143: 10000 | R143: 5900000 | S143: 18870 | T143: 58889.288 | V143: 5859980.7 | W143: 585.99807 | X143: 5900000 | Y143: 18870 | Z143: 58889.288 | AB143: 5859980.7 | AC143: 585.99807
A144: ITBISA-IC-NE555P-DIP8 | B144: 46052.484 | C144: 46116.701 | D144: KYAI KONTONG | E144: TRUE | F144: Ocistok/Martkita | G144: https://detail.1688.com/offer/624513627642.html | H144: MKT-137394 / 319511 | I144: 5 | J144: 10000 | K144: 1 | L144: =(318)/P144 -> 318 | M144: =(18870)/P144 -> 18870 | N144: =(500000)*(R144/50094000) -> 31740.328 | P144: 1 | Q144: 10000 | R144: 3180000 | S144: 18870 | T144: 31740.328 | V144: 3167129.7 | W144: 316.71297 | X144: 3180000 | Y144: 18870 | Z144: 31740.328 | AB144: 3167129.7 | AC144: 316.71297
A145: ITBISA-IDC-2X5-AMPHENOL-FEMALE | B145: 46054.205 | C145: 46060.507 | D145: KYAI KONTONG | E145: FALSE | F145: Shopee | G145: Duta Part | H145: Shopee Aji HDC8 | I145: 5 | J145: 27 | K145: 1 | L145: =(750)/P145 -> 750 | M145: =(1000)/P145 -> 1000 | N145: =(4000)/P145 -> 4000 | P145: 1 | Q145: 27 | R145: 20250 | S145: 1000 | T145: 4000 | V145: 17250 | W145: 638.88889 | X145: 20250 | Y145: 1000 | Z145: 4000 | AB145: 17250 | AC145: 638.88889
A146: ITBISA-RELAY-12V-5PIN-BLUE | B146: 46054.216 | C146: 46060.481 | D146: KYAI KONTONG | E146: FALSE | F146: Shopee | G146: Golden Dream Official Shop | H146: Shopee Aji CSTS | I146: 5 | J146: 580 | K146: 1 | L146: =(2300)/P146 -> 2300 | M146: =(3000)/P146 -> 3000 | N146: =(199725 + 2500)/P146 -> 202225 | O146: 0 | P146: 1 | Q146: 580 | R146: 1334000 | S146: 3000 | T146: 202225 | V146: 1134775 | W146: 1956.5086 | X146: 1334000 | Y146: 3000 | Z146: 202225 | AB146: 1134775 | AC146: 1956.5086
A147: ITBISA-CHIP-ESP8266-ESP12F | B147: 46059.84 | C147: 46062.614 | D147: KYAI KONTONG | E147: FALSE | F147: Shopee | G147: CNC Store Jogja | H147: Shopee Aji WYU3 | I147: 5 | J147: 16 | K147: 1 | L147: =(18800)/P147 -> 18800 | M147: =(3000)/P147 -> 3000 | N147: =(99264)/P147 -> 99264 | P147: 1 | Q147: 16 | R147: 300800 | S147: 3000 | T147: 99264 | V147: 204536 | W147: 12783.5 | X147: 300800 | Y147: 3000 | Z147: 99264 | AB147: 204536 | AC147: 12783.5
A148: ITBISA-KAPASITOR-ELCO-2200UF-25V | B148: 46061.835 | C148: 46064.588 | D148: KERTASARI CIAMIS | E148: FALSE | F148: Shopee | G148: NE Elektronik | H148: Shopee Aji SPUV | I148: 5 | J148: 310 | K148: 1 | L148: =(975)/P148 -> 975 | M148: =(3000)/P148 -> 3000 | N148: =(99743)/P148 -> 99743 | P148: 1 | Q148: 310 | R148: 302250 | S148: 3000 | T148: 99743 | V148: 205507 | W148: 662.92581 | X148: 302250 | Y148: 3000 | Z148: 99743 | AB148: 205507 | AC148: 662.92581
A149: ITBISA-IC-PC817-DIP4 | B149: 46061.838 | C149: 46065.319 | D149: KYAI KONTONG | E149: FALSE | F149: Shopee | G149: DN TRONIC | H149: Shopee Anggi R9UK | I149: 5 | J149: 759 | K149: 1 | L149: =(399)/P149 -> 399 | M149: =(3000)/P149 -> 3000 | N149: =(99938)/P149 -> 99938 | P149: 1 | Q149: 759 | R149: 302841 | S149: 3000 | T149: 99938 | V149: 205903 | W149: 271.28195 | X149: 302841 | Y149: 3000 | Z149: 99938 | AB149: 205903 | AC149: 271.28195
...

Sheet BisaHilang
A1: Tanggal Pengecekan Kehilangan | B1: SKU | C1: Banyak Ketemu | D1: Nilai Ketemu | E1: Banyak Hilang | F1: Nilai Hilang | G1: Lokasi Gudang | H1: Keterangan
A3: 46023.042 | B3: ITBISA-BUBBLE-WRAP | C3: 1 | D3: 1 | G3: KYAI KONTONG
A4: 46023.042 | B4: ITBISA-BUBBLE-WRAP | E4: 1 | F4: 1 | G4: KYAI KONTONG
A6: 46044.169 | B6: ITBISA-IC-LM741CN-DIP8 | E6: 20 | F6: =E6*1291.1 -> 25822 | G6: KYAI KONTONG
A7: 46044.169 | B7: ITBISA-IC-UA741CN-DIP8 | C7: 20 | D7: =C7*572 -> 11440 | G7: KYAI KONTONG
A8: 46044.169 | B8: ITBISA-7SEGMENT-CATHODE-RED-1.20-1BIT | C8: =(339 - 292) -> 47 | D8: =C8*2756 -> 129532 | G8: KYAI KONTONG
A9: 46044.169 | B9: ITBISA-7SEGMENT-CATHODE-RED-2.30-1BIT | C9: =(58-42) -> 16 | D9: =C9*6028 -> 96448 | G9: KYAI KONTONG
A10: 46044.169 | B10: ITBISA-BLUETOOTH-MODULE-HC05 | E10: =(27-15) -> 12 | F10: =E10*29027 -> 348324 | G10: KYAI KONTONG
A11: 46044.169 | B11: ITBISA-IC-NE555P-DIP8 | E11: =(825-313) -> 512 | F11: =E11*288.89 -> 147911.68 | G11: KYAI KONTONG
A12: 46044.169 | B12: ITBISA-IC-PC817-DIP4 | E12: =(852-473) -> 379 | F12: =E12*340.35 -> 128992.65 | G12: KYAI KONTONG
A13: 46044.169 | B13: ITBISA-RELAY-5V-1CHANNEL-BLUE-LOW-TRIGGER | E13: =(8-5) -> 3 | F13: =E13*4252.52 -> 12757.56 | G13: KYAI KONTONG
A14: 46044.169 | B14: ITBISA-SERVO-SG90-180DEG | C14: =(13-8) -> 5 | D14: =C14* 10459.32 -> 52296.6 | G14: KYAI KONTONG
A15: 46044.169 | B15: ITBISA-SERVO-SG90-360DEG | C15: =(5-3) -> 2 | D15: =C15* 11352.67 -> 22705.34 | G15: KYAI KONTONG
A16: 46044.169 | B16: ITBISA-SOCKET-IC-DIP14-NARROW | C16: =(123-25) -> 98 | D16: =C16* 222.05 -> 21760.9 | G16: KYAI KONTONG
A17: 46044.169 | B17: ITBISA-CHIP-ESP32-WROOM-ANTENNA | E17: 6 | F17: =E17*24820 -> 148920 | G17: KYAI KONTONG
A19: 46046.137 | B19: ITBISA-7SEGMENT-ANODE-RED-0.56-1BIT | E19: 160 | F19: =E19*675.92 -> 108147.2 | G19: KERTASARI CIAMIS
A20: 46046.137 | B20: ITBISA-IC-CD4094BM-SMD-SOP16 | E20: =494-130 -> 364 | F20: =E20*874.83 -> 318438.12 | G20: KERTASARI CIAMIS
A21: 46046.137 | B21: ITBISA-IC-CD4094BM-SMD-SOP16 | E21: 45 | F21: =E21*874.83 -> 39367.35 | G21: KERTASARI CIAMIS
A22: 46046.137 | B22: ITBISA-7SEGMENT-CATHODE-RED-1.20-1BIT | E22: =(87-52) -> 35 | F22: =E22*2756 -> 96460 | G22: KERTASARI CIAMIS
A23: 46046.137 | B23: ITBISA-7SEGMENT-CATHODE-RED-2.30-1BIT | C23: =(36-8) -> 28 | D23: =C23*6028 -> 168784 | G23: KERTASARI CIAMIS
A24: 46046.137 | B24: ITBISA-ABC-BATERAI-AA-ALKALINE | E24: =(155-94) -> 61 | F24: =E24*3900 -> 237900 | G24: KERTASARI CIAMIS
A25: 46046.137 | B25: ITBISA-ABC-BATERAI-AAA-ALKALINE | C25: =(38-35) -> 3 | D25: =C25*3612.53 -> 10837.59 | G25: KERTASARI CIAMIS
A26: 46046.137 | B26: ITBISA-BREADBOARD-830HOLE-MB102 | C26: =(32-23) -> 9 | D26: =C26*7000 -> 63000 | G26: KERTASARI CIAMIS
A27: 46046.137 | B27: ITBISA-CHIP-ESP32-WROOM | C27: =(21-14) -> 7 | D27: =(C27*23076) -> 161532 | G27: KERTASARI CIAMIS
A28: 46046.137 | B28: ITBISA-I2C-IIC-LCD | C28: =(44-31) -> 13 | D28: =C28*5617.6 -> 73028.8 | G28: KERTASARI CIAMIS
A29: 46046.137 | B29: ITBISA-LDR-GL5516 | E29: =(79-47) -> 32 | F29: =E29*285.14 -> 9124.48 | G29: KERTASARI CIAMIS
A30: 46046.137 | B30: ITBISA-LED-MAX7219-4IN1-TIGHT | E30: 1 | F30: =E30*35799.38 -> 35799.38 | G30: KERTASARI CIAMIS
A31: 46046.137 | B31: ITBISA-PIN-HEADER-MALE-1X40PIN-L-SAMA | E31: 7 | F31: =E31*726.09 -> 5082.63 | G31: KERTASARI CIAMIS
A32: 46046.137 | B32: ITBISA-RELAY-12V-4PIN-BLUE | C32: =(400)-291 -> 109 | D32: =C32*1637 -> 178433 | G32: KERTASARI CIAMIS
A33: 46046.137 | B33: ITBISA-RELAY-12V-5PIN-BLUE | E33: 10 | F33: =E33*1980.5 -> 19805 | G33: KERTASARI CIAMIS
A34: 46046.137 | B34: ITBISA-SERVO-SG90-180DEG | E34: =(56-37) -> 19 | F34: =E34* 10459.32 -> 198727.08 | G34: KERTASARI CIAMIS
A35: 46046.137 | B35: ITBISA-SERVO-SG90-360DEG | E35: =(35-30) -> 5 | F35: =E35* 11352.67 -> 56763.35 | G35: KERTASARI CIAMIS
A36: 46046.137 | B36: ITBISA-SOCKET-IC-DIP20-NARROW | C36: =(103-33) -> 70 | D36: =C36*535 -> 37450 | G36: KERTASARI CIAMIS
A37: 46046.137 | B37: ITBISA-WEMOS-D1-MINI-ESP8266 | E37: 1 | F37: =E37*20791.2 -> 20791.2 | G37: KERTASARI CIAMIS
A38: 46046.137 | B38: ITBISA-IC-NE555P-DIP8 | E38: =(161-58) -> 103 | F38: =E38*316.71 -> 32621.13 | G38: KYAI KONTONG
A40: 46081.674 | B40: ITBISA-CHIP-ESP8266-ESP12F | E40: 17 | F40: =E40*12783.5 -> 217319.5 | G40: KERTASARI CIAMIS
A41: 46081.674 | B41: ITBISA-RTC-DS3231SN | E41: 4 | F41: =E41*19398 -> 77592 | G41: KYAI KONTONG
A42: 46081.674 | B42: ITBISA-SERVO-SG90-360DEG | C42: 3 | D42: =C42* 11352.67 -> 34058.01 | G42: KYAI KONTONG
A43: 46081.674 | B43: ITBISA-CHIP-ESP8266-ESP12F | E43: 3 | F43: =E43*12783.5 -> 38350.5 | G43: KERTASARI CIAMIS
A44: 46081.674 | B44: ITBISA-CHIP-ESP8266-ESP12F | E44: 18 | F44: =E44*12783.5 -> 230103 | G44: KERTASARI CIAMIS
...

Sheet BisaRekapBarang
D1: TRUE | E1: FALSE | F1: FALSE | G1: FALSE | H1: FALSE | I1: FALSE | J1: FALSE | K1: FALSE | L1: FALSE | M1: FALSE | N1: FALSE
A2: {={BisaRekapBarangBackend!A1:C1;SORT(IF(BisaRekapBarangBackend!B2:B140<1,,BisaRekapBarangBackend!A2:C140),1,TRUE)}} -> Alamat Penerima | B2: Harga Impor Barang (Rupiah) | C2: Harga Impor Barang (USD) | D2: {={BisaRekapBarangBackend!D1:O1; SORT(IF( (BisaRekapBarangBackend!D2:D140="ITBISA-KODE-UNIK")+(BisaRekapBarangBackend!H2:H140=0),,BisaRekapBarangBackend!D2:O140), IF(D1=TRUE,1, IF(E1=TRUE,2, IF(F1=TRUE,3, IF(G1=TRUE,4, IF(H1=TRUE,5, IF(I1=TRUE,6, IF(J1=TRUE,7, IF(K1=TRUE,8, IF(L1=TRUE,9, IF(M1=TRUE,10, IF(N1=TRUE,11, IF(#REF!=TRUE,12,1)))))))))))), IF(D1=TRUE,TRUE, IF(E1=TRUE,TRUE, IF(F1=TRUE,TRUE, IF(G1=TRUE,FALSE, IF(H1=TRUE,FALSE, IF(I1=TRUE,FALSE, IF(J1=TRUE,FALSE, IF(K1=TRUE,FALSE, IF(L1=TRUE,FALSE, IF(M1=TRUE,FALSE, IF(N1=TRUE,FALSE, IF(#REF!=TRUE,FALSE)))))))))))), 1,TRUE)}} -> SKU | E2: Tanggal Pesan Terakhir | F2: HPP Terakhir | G2: HPP Belum Terjual | H2: Total Stok | I2: 1/2 Total Stok | J2: 1/3 Total Stok | K2: 40% Total Stok | L2: 20% Total Stok | M2: KERTASARI CIAMIS | N2: KYAI KONTONG
A3: KYAI KONTONG | B3: 100503000 | C3: 5600.3009 | D3: ITBISA-7SEGMENT-ANODE-RED-0.56-1BIT | E3: 46197 | F3: 675.92 | G3: 2867252.6 | H3: 4242 | I3: 2121 | J3: 1414 | K3: 1696 | L3: 848 | N3: 4242
D4: ITBISA-7SEGMENT-ANODE-RED-1.00-1BIT | E4: 46197 | F4: 2000 | G4: 4016000 | H4: 2008 | I4: 1004 | J4: 669 | K4: 803 | L4: 401 | N4: 2008
D5: ITBISA-7SEGMENT-ANODE-RED-1.20-1BIT | E5: 46193 | F5: 3611.73 | G5: 2235660.9 | H5: 619 | I5: 309 | J5: 206 | K5: 247 | L5: 123 | N5: 619
D6: ITBISA-7SEGMENT-CATHODE-RED-0.56-1BIT | E6: 46196 | F6: 731 | G6: 3655 | H6: 5 | I6: 2 | J6: 1 | K6: 2 | L6: 1 | N6: 5
D7: ITBISA-7SEGMENT-CATHODE-RED-1.20-1BIT | E7: 46176 | F7: 2756 | G7: 55120 | H7: 20 | I7: 10 | J7: 6 | K7: 8 | L7: 4 | N7: 20
D8: ITBISA-7SEGMENT-CATHODE-RED-2.30-1BIT | E8: 46179 | F8: 6462.2939 | G8: 38773.763 | H8: 6 | I8: 3 | J8: 2 | K8: 2 | L8: 1 | N8: 6
D9: ITBISA-ABC-BATERAI-9V-POWER | E9: 46192 | F9: 11210.938 | G9: 1244414.1 | H9: 111 | I9: 55 | J9: 37 | K9: 44 | L9: 22 | N9: 111
D10: ITBISA-ABC-BATERAI-AA-ALKALINE | E10: 46198 | F10: 3987.5 | G10: 1375687.5 | H10: 345 | I10: 172 | J10: 115 | K10: 138 | L10: 69 | N10: 345
D11: ITBISA-ABC-BATERAI-AAA-ALKALINE | E11: 46198 | F11: 3117.1667 | G11: 1362201.8 | H11: 437 | I11: 218 | J11: 145 | K11: 174 | L11: 87 | N11: 437
D12: ITBISA-ABC-BATERAI-D-POWER | F12: 5166.67 | G12: 5166.67 | H12: 1 | I12: 0 | J12: 0 | K12: 0 | L12: 0 | N12: 1
D13: ITBISA-ARDUINO-UNO-R3-328P-SMD | E13: 46196 | F13: 37978.26 | G13: 8469152 | H13: 223 | I13: 111 | J13: 74 | K13: 89 | L13: 44 | N13: 223
D14: ITBISA-BLUETOOTH-MODULE-HC05 | E14: 46196 | F14: 21771.152 | G14: 4288916.8 | H14: 197 | I14: 98 | J14: 65 | K14: 78 | L14: 39 | N14: 197
D15: ITBISA-BUBBLE-WRAP | E15: 46134 | G15: 0 | H15: 12 | I15: 6 | J15: 4 | K15: 4 | L15: 2 | N15: 12
D16: ITBISA-BUZZER-ACTIVE-5V | E16: 46198 | F16: 1250.5138 | G16: 3372635.7 | H16: 2697 | I16: 1348 | J16: 899 | K16: 1078 | L16: 539 | N16: 2697
D17: ITBISA-CHIP-ESP8266-ESP12F | E17: 46077 | F17: 12783.5 | G17: 485773 | H17: 38 | I17: 19 | J17: 12 | K17: 15 | L17: 7 | N17: 38
D18: ITBISA-DC-TO-DC-STEPDOWN-XL4005 | E18: 46198 | F18: 8461.03 | G18: 126915.45 | H18: 15 | I18: 7 | J18: 5 | K18: 6 | L18: 3 | N18: 15
D19: ITBISA-DC-TO-DC-STEPUP-XL6009 | E19: 46197 | F19: 7240.2871 | G19: 202728.04 | H19: 28 | I19: 14 | J19: 9 | K19: 11 | L19: 5 | N19: 28
D20: ITBISA-DIODA-1N4007-DO41 | E20: 46185 | F20: 78.561407 | G20: 154765.97 | H20: 1970 | I20: 985 | J20: 656 | K20: 788 | L20: 394 | N20: 1970
D21: ITBISA-I2C-IIC-LCD | E21: 46198 | F21: 5806.3269 | G21: 168383.48 | H21: 29 | I21: 14 | J21: 9 | K21: 11 | L21: 5 | N21: 29
D22: ITBISA-IC-74HC245N-DIP20 | E22: 46195 | F22: 1425.7829 | G22: 4030688.3 | H22: 2827 | I22: 1413 | J22: 942 | K22: 1130 | L22: 565 | N22: 2827
D23: ITBISA-IC-74HC595N-DIP16 | E23: 46185 | F23: 768.24276 | G23: 768.24276 | H23: 1 | I23: 0 | J23: 0 | K23: 0 | L23: 0 | N23: 1
D24: ITBISA-IC-ATMEGA328P-DIP28 | E24: 46197 | F24: 27318.46 | G24: 4125087.5 | H24: 151 | I24: 75 | J24: 50 | K24: 60 | L24: 30 | N24: 151
D25: ITBISA-IC-CD4017BE-DIP16 | E25: 46195 | F25: 684.887 | G25: 4794.209 | H25: 7 | I25: 3 | J25: 2 | K25: 2 | L25: 1 | N25: 7
D26: ITBISA-IC-CD4094BE-DIP16 | E26: 46198 | F26: 779.54 | G26: 6587113 | H26: 8450 | I26: 4225 | J26: 2816 | K26: 3380 | L26: 1690 | N26: 8450
D27: ITBISA-IC-CD4094BM-SMD-SOP16 | E27: 46195 | F27: 747.90909 | G27: 3343153.6 | H27: 4470 | I27: 2235 | J27: 1490 | K27: 1788 | L27: 894 | N27: 4470
... D30: ITBISA-IC-L7812CV-TO220 | E30: 46197 | F30: 1057 | G30: 1057 | H30: 1 | I30: 0 | J30: 0 | K30: 0 | L30: 0 | N30: 1
D31: ITBISA-IC-LM741CN-DIP8 | F31: 1291.1 | G31: 1291.1 | H31: 1 | I31: 0 | J31: 0 | K31: 0 | L31: 0 | N31: 1
D32: ITBISA-IC-NE555P-DIP8 | E32: 46197 | F32: 476.82927 | G32: 185486.59 | H32: 389 | I32: 194 | J32: 129 | K32: 155 | L32: 77 | N32: 389
D33: ITBISA-IC-PC817-DIP4 | E33: 46198 | F33: 340.065 | G33: 1305509.5 | H33: 3839 | I33: 1919 | J33: 1279 | K33: 1535 | L33: 767 | N33: 3839
D34: ITBISA-IC-UA741CN-DIP8 | E34: 46198 | F34: 572 | G34: 787644 | H34: 1377 | I34: 688 | J34: 459 | K34: 550 | L34: 275 | N34: 1377
D35: ITBISA-IC-ULN2003AN-DIP16 | E35: 46196 | F35: 855.5 | G35: 1255018.5 | H35: 1467 | I35: 733 | J35: 489 | K35: 586 | L35: 293 | N35: 1467
D36: ITBISA-IC-ULN2803APG-DIP18 | E36: 46191 | F36: 1018 | G36: 1018 | H36: 1 | I36: 0 | J36: 0 | K36: 0 | L36: 0 | N36: 1
D37: ITBISA-IDC-2X5-AMPHENOL-FEMALE | E37: 46179 | F37: 369.94038 | G37: 723603.38 | H37: 1956 | I37: 978 | J37: 652 | K37: 782 | L37: 391 | N37: 1956
D38: ITBISA-IDC-2X5-AMPHENOL-MALE | E38: 46158 | F38: 585.4 | G38: 440220.8 | H38: 752 | I38: 376 | J38: 250 | K38: 300 | L38: 150 | N38: 752
D39: ITBISA-JACK-DC-005-FEMALE | E39: 46198 | F39: 248.68687 | G39: 438186.26 | H39: 1762 | I39: 881 | J39: 587 | K39: 704 | L39: 352 | N39: 1762
D40: ITBISA-JUMPER-FF-10CM | E40: 46196 | F40: 90.005507 | G40: 500430.62 | H40: 5560 | I40: 2780 | J40: 1853 | K40: 2224 | L40: 1112 | N40: 5560
D41: ITBISA-JUMPER-FF-20CM | E41: 46196 | F41: 165.06 | G41: 1023372 | H41: 6200 | I41: 3100 | J41: 2066 | K41: 2480 | L41: 1240 | N41: 6200
D42: ITBISA-JUMPER-MF-10CM | E42: 46197 | F42: 165.05 | G42: 1089330 | H42: 6600 | I42: 3300 | J42: 2200 | K42: 2640 | L42: 1320 | N42: 6600
...

Sheet BisaPindahBarang
A1: Tanggal | C1: Lokasi Penambahan Barang | D1: Lokasi Pengurangan Barang | E1: Banyak Barang | F1: Keterangan
A3: 46023 | B3: ITBISA-7SEGMENT-ANODE-RED-0.56-1BIT | C3: KERTASARI CIAMIS | D3: KYAI KONTONG | E3: 255
A4: 46023 | B4: ITBISA-7SEGMENT-ANODE-RED-1.00-1BIT | C4: KERTASARI CIAMIS | D4: KYAI KONTONG | E4: 519
A5: 46023 | B5: ITBISA-7SEGMENT-ANODE-RED-1.20-1BIT | C5: KERTASARI CIAMIS | D5: KYAI KONTONG | E5: 782
A6: 46023 | B6: ITBISA-7SEGMENT-CATHODE-RED-0.56-1BIT | C6: KERTASARI CIAMIS | D6: KYAI KONTONG | E6: 1752
A7: 46023 | B7: ITBISA-7SEGMENT-CATHODE-RED-1.20-1BIT | C7: KERTASARI CIAMIS | D7: KYAI KONTONG | E7: 87
A8: 46023 | B8: ITBISA-7SEGMENT-CATHODE-RED-2.30-1BIT | C8: KERTASARI CIAMIS | D8: KYAI KONTONG | E8: 8
A9: 46023 | B9: ITBISA-ABC-BATERAI-9V-POWER | C9: KERTASARI CIAMIS | D9: KYAI KONTONG | E9: 8
A10: 46023 | B10: ITBISA-ABC-BATERAI-AA-ALKALINE | C10: KERTASARI CIAMIS | D10: KYAI KONTONG | E10: 250
A11: 46023 | B11: ITBISA-ABC-BATERAI-AAA-ALKALINE | C11: KERTASARI CIAMIS | D11: KYAI KONTONG | E11: 35
A12: 46023 | B12: ITBISA-ABC-BATERAI-D-POWER | C12: KERTASARI CIAMIS | D12: KYAI KONTONG
A13: 46023 | B13: ITBISA-ARDUINO-UNO-R3-328P-SMD | C13: KERTASARI CIAMIS | D13: KYAI KONTONG | E13: 221
A14: 46023 | B14: ITBISA-BLUETOOTH-MODULE-HC05 | C14: KERTASARI CIAMIS | D14: KYAI KONTONG | E14: 6
A15: 46023 | B15: ITBISA-BREADBOARD-830HOLE-MB102 | C15: KERTASARI CIAMIS | D15: KYAI KONTONG | E15: 24
A16: 46023 | B16: ITBISA-BUBBLE-WRAP | C16: KERTASARI CIAMIS | D16: KYAI KONTONG | E16: -11
A17: 46023 | B17: ITBISA-BUZZER-ACTIVE-5V | C17: KERTASARI CIAMIS | D17: KYAI KONTONG | E17: 1037
A18: 46023 | B18: ITBISA-CHIP-ESP32-WROOM | C18: KERTASARI CIAMIS | D18: KYAI KONTONG | E18: 22
A19: 46023 | B19: ITBISA-CHIP-ESP32-WROOM-ANTENNA | C19: KERTASARI CIAMIS | D19: KYAI KONTONG
A20: 46023 | B20: ITBISA-SOCKET-IC-DIP28-NARROW | C20: KERTASARI CIAMIS | D20: KYAI KONTONG | E20: 20
A21: 46023 | B21: ITBISA-DC-TO-DC-STEPDOWN-LM2596 | C21: KERTASARI CIAMIS | D21: KYAI KONTONG | E21: 101
A22: 46023 | B22: ITBISA-DC-TO-DC-STEPDOWN-XL4005 | C22: KERTASARI CIAMIS | D22: KYAI KONTONG | E22: 67
A23: 46023 | B23: ITBISA-DC-TO-DC-STEPDOWN-XL4015 | C23: KERTASARI CIAMIS | D23: KYAI KONTONG | E23: 119
A24: 46023 | B24: ITBISA-DC-TO-DC-STEPUP-XL6009 | C24: KERTASARI CIAMIS | D24: KYAI KONTONG | E24: 191
A25: 46023 | B25: ITBISA-I2C-IIC-LCD | C25: KERTASARI CIAMIS | D25: KYAI KONTONG | E25: 31
A26: 46023 | B26: ITBISA-IC-74HC595N-DIP16 | C26: KERTASARI CIAMIS | D26: KYAI KONTONG | E26: 14
A27: 46023 | B27: ITBISA-IC-ATMEGA328P-DIP28 | C27: KERTASARI CIAMIS | D27: KYAI KONTONG | E27: 159
A28: 46023 | B28: ITBISA-IC-CD4017BE-DIP16 | C28: KERTASARI CIAMIS | D28: KYAI KONTONG
A29: 46023 | B29: ITBISA-IC-CD4094BE-DIP16 | C29: KERTASARI CIAMIS | D29: KYAI KONTONG
A30: 46023 | B30: ITBISA-IC-CD4094BM-SMD-SOP16 | C30: KERTASARI CIAMIS | D30: KYAI KONTONG | E30: 494
A31: 46023 | B31: ITBISA-IC-JRC4558D-DIP8 | C31: KERTASARI CIAMIS | D31: KYAI KONTONG | E31: 1000
A32: 46023 | B32: ITBISA-IC-L7805CV-TO220 | C32: KERTASARI CIAMIS | D32: KYAI KONTONG | E32: 932
A33: 46023 | B33: ITBISA-IC-L7812CV-TO220 | C33: KERTASARI CIAMIS | D33: KYAI KONTONG | E33: 802
A34: 46023 | B34: ITBISA-IC-LM741CN-DIP8 | C34: KERTASARI CIAMIS | D34: KYAI KONTONG
A35: 46023 | B35: ITBISA-IC-NE555P-DIP8 | C35: KERTASARI CIAMIS | D35: KYAI KONTONG | E35: 2992
A36: 46023 | B36: ITBISA-IC-PC817-DIP4 | C36: KERTASARI CIAMIS | D36: KYAI KONTONG | E36: 1748
A37: 46023 | B37: ITBISA-IC-UA741CN-DIP8 | C37: KERTASARI CIAMIS | D37: KYAI KONTONG | E37: 4619
A38: 46023 | B38: ITBISA-IC-ULN2003AN-DIP16 | C38: KERTASARI CIAMIS | D38: KYAI KONTONG | E38: 1214
A39: 46023 | B39: ITBISA-IC-ULN2803APG-DIP18 | C39: KERTASARI CIAMIS | D39: KYAI KONTONG | E39: 423
A40: 46023 | B40: ITBISA-IDC-2X5-AMPHENOL-FEMALE | C40: KERTASARI CIAMIS | D40: KYAI KONTONG | E40: 1021
A41: 46023 | B41: ITBISA-IDC-2X5-AMPHENOL-MALE | C41: KERTASARI CIAMIS | D41: KYAI KONTONG | E41: 412
...

Sheet BisaSEO
A1: SKU | B1: Kata Kunci Utama | C1: Jenis Barang | D1: Keterangan Barang (Ukuran, Warna) | E1: Fungsi Barang (Opsional) | F1: Typo | G1: BisaDivisi | H1: Massa (g) | I1: Tagar | J1: {={"Hitung Tagar";IF(I2:I978="",,LEN(I2:I978)-LEN(SUBSTITUTE(I2:I978,"#","")))}} -> Hitung Tagar | K1: {={"Nama Lengkap";IF(G2:G978="",, TRIM("ITBisa - "&IF(B2:B978="",,B2:B978)&" "&IF(C2:C978="",,C2:C978 )&" "&IF(D2:D978="",,D2:D978)& " "&IF(E2:E978="",,E2:E978)&" "&IF(F2:F978="",,F2:F978)))}} -> Nama Lengkap | L1: {={"Nama Tokopedia (70 Karakter)";IF(K2:K978="",,LEFT(TRIM(K2:K978),70))}} -> Nama Tokopedia (70 Karakter) | M1: {={"Nama Bukalapak (150 Karakter)";IF(K2:K978="",,LEFT(TRIM(K2:K978),150))}} -> Nama Bukalapak (150 Karakter) | N1: {={"Nama Shopee (255 Karakter)";IF(K2:K978="",,LEFT(TRIM(K2:K978),255))}} -> Nama Shopee (255 Karakter) | O1: Link Bukalapak | P1: Link Tokopedia | Q1: Link Shopee
A2: ITBISA-7SEGMENT-ANODE-RED-0.56-1BIT | B2: Seven 7 Segment | C2: CA Common Anode | D2: 0.56 Inch Red 1BIT | E2: LED Merah Display Jam Digital Nilai Sensor | F2: 7-Segment Anoda 0,56" Inci 0.56" 0.56inch 1 BIT | G2: BisaElektronika - BisaSegment | H2: 3 | I2: #ITBisa #BisaElektronika #BisaSegment #7Segment #Segment #CA #CC #Anode #Cathode #0.56 #LED #1BIT #Red #Arduino #Counter #Digital #IC #Mikrokontroler #Timer #Clock | J2: 20 | K2: ITBisa - Seven 7 Segment CA Common Anode 0.56 Inch Red 1BIT LED Merah Display Jam Digital Nilai Sensor 7-Segment Anoda 0,56" Inci 0.56" 0.56inch 1 BIT | L2: ITBisa - Seven 7 Segment CA Common Anode 0.56 Inch Red 1BIT LED Merah | M2: ITBisa - Seven 7 Segment CA Common Anode 0.56 Inch Red 1BIT LED Merah Display Jam Digital Nilai Sensor 7-Segment Anoda 0,56" Inci 0.56" 0.56inch 1 BIT | N2: ITBisa - Seven 7 Segment CA Common Anode 0.56 Inch Red 1BIT LED Merah Display Jam Digital Nilai Sensor 7-Segment Anoda 0,56" Inci 0.56" 0.56inch 1 BIT | O2: https://www.bukalapak.com/p/elektronik/komponen-elektronik/12cm7sr-jual-itbisa-7-segment-cc-common-katoda-0-56-inci-merah-1-bit-led-display-jam-digital-nilai-sensor-7-segment-seven-red-cathode-0-56inch-inch-1bit | P2: https://tokopedia.com/itbisa/itbisa-seven-7-segment-cc-common-cathode-0-56-inch-red-1bit-merah
A3: ITBISA-7SEGMENT-ANODE-RED-1.00-1BIT | B3: Seven 7 Segment | C3: CA Common Anode | D3: 1 Inch Red 1BIT | E3: LED Merah Display Jam Digital Nilai Sensor | F3: 7-Segment Anoda 1" Inch 1inch BIT | G3: BisaElektronika - BisaSegment | H3: 3 | K3: ITBisa - Seven 7 Segment CA Common Anode 1 Inch Red 1BIT LED Merah Display Jam Digital Nilai Sensor 7-Segment Anoda 1" Inch 1inch BIT | L3: ITBisa - Seven 7 Segment CA Common Anode 1 Inch Red 1BIT LED Merah Dis | M3: ITBisa - Seven 7 Segment CA Common Anode 1 Inch Red 1BIT LED Merah Display Jam Digital Nilai Sensor 7-Segment Anoda 1" Inch 1inch BIT | N3: ITBisa - Seven 7 Segment CA Common Anode 1 Inch Red 1BIT LED Merah Display Jam Digital Nilai Sensor 7-Segment Anoda 1" Inch 1inch BIT | O3: https://www.bukalapak.com/p/elektronik/komponen-elektronik/12cn11o-jual-itbisa-ic-ua741cn-dip-8-op-amp-filter-penguat-lpf-hpf-bpf-integrated-circuit-ua-741-ua741-op-amp-opamp-8-pin-kaki-dip8-8dip
A4: ITBISA-7SEGMENT-ANODE-RED-1.20-1BIT | B4: Seven 7 Segment | C4: CA Common Anode | D4: 1.2 Inch Red 1BIT | E4: LED Merah Display Jam Digital Nilai Sensor | F4: 7-Segment Anoda 1,2" Inci 1.2" 1.2inch 1 BIT | G4: BisaElektronika - BisaSegment | H4: 3 | I4: #ITBisa #BisaElektronika #BisaSegment #7Segment #Segment #CA #CC #Anode #Cathode #0.56 #LED #1BIT #Red #Arduino #Counter #Digital #IC #Mikrokontroler #Timer #Clock | J4: 20 | K4: ITBisa - Seven 7 Segment CA Common Anode 1.2 Inch Red 1BIT LED Merah Display Jam Digital Nilai Sensor 7-Segment Anoda 1,2" Inci 1.2" 1.2inch 1 BIT | L4: ITBisa - Seven 7 Segment CA Common Anode 1.2 Inch Red 1BIT LED Merah D | M4: ITBisa - Seven 7 Segment CA Common Anode 1.2 Inch Red 1BIT LED Merah Display Jam Digital Nilai Sensor 7-Segment Anoda 1,2" Inci 1.2" 1.2inch 1 BIT | N4: ITBisa - Seven 7 Segment CA Common Anode 1.2 Inch Red 1BIT LED Merah Display Jam Digital Nilai Sensor 7-Segment Anoda 1,2" Inci 1.2" 1.2inch 1 BIT
A5: ITBISA-7SEGMENT-ANODE-RED-2.30-1BIT | B5: Seven 7 Segment | C5: HS 23101 BS CA Anode Jam Masjid | D5: 2.30 Inch Red 1BIT | E5: LED Display Digital | F5: 7-Segment Anoda 2,3" Inci 2.3" 2.3inch 1 BIT | G5: BisaElektronika - BisaSegment | I5: #ITBisa #BisaElektronika #BisaSegment #7Segment #Segment #CA #CC #Anode #Cathode #0.56 #LED #1BIT #Red #Arduino #Counter #Digital #IC #Mikrokontroler #Timer #Clock | J5: 20 | K5: ITBisa - Seven 7 Segment HS 23101 BS CA Anode Jam Masjid 2.30 Inch Red 1BIT LED Display Digital 7-Segment Anoda 2,3" Inci 2.3" 2.3inch 1 BIT | L5: ITBisa - Seven 7 Segment HS 23101 BS CA Anode Jam Masjid 2.30 Inch Red | M5: ITBisa - Seven 7 Segment HS 23101 BS CA Anode Jam Masjid 2.30 Inch Red 1BIT LED Display Digital 7-Segment Anoda 2,3" Inci 2.3" 2.3inch 1 BIT | N5: ITBisa - Seven 7 Segment HS 23101 BS CA Anode Jam Masjid 2.30 Inch Red 1BIT LED Display Digital 7-Segment Anoda 2,3" Inci 2.3" 2.3inch 1 BIT
A6: ITBISA-7SEGMENT-CATHODE-RED-0.56-1BIT | B6: Seven 7 Segment | C6: CC Common Cathode | D6: 0.56 Inch Red 1BIT | E6: LED Merah Display Jam Digital Nilai Sensor | F6: 7-Segment Katoda 0,56" Inci 0.56" 0.56inch 1 BIT | G6: BisaElektronika - BisaSegment | H6: 3 | I6: #ITBisa #BisaElektronika #BisaSegment #7Segment #Segment #CA #CC #Anode #Cathode #0.56 #LED #1BIT #Red #Arduino #Counter #Digital #IC #Mikrokontroler #Timer #Clock | J6: 20 | K6: ITBisa - Seven 7 Segment CC Common Cathode 0.56 Inch Red 1BIT LED Merah Display Jam Digital Nilai Sensor 7-Segment Katoda 0,56" Inci 0.56" 0.56inch 1 BIT | L6: ITBisa - Seven 7 Segment CC Common Cathode 0.56 Inch Red 1BIT LED Mera | M6: ITBisa - Seven 7 Segment CC Common Cathode 0.56 Inch Red 1BIT LED Merah Display Jam Digital Nilai Sensor 7-Segment Katoda 0,56" Inci 0.56" 0.56inch 1 | N6: ITBisa - Seven 7 Segment CC Common Cathode 0.56 Inch Red 1BIT LED Merah Display Jam Digital Nilai Sensor 7-Segment Katoda 0,56" Inci 0.56" 0.56inch 1 BIT
A7: ITBISA-7SEGMENT-CATHODE-RED-1.00-1BIT | B7: Seven 7 Segment | C7: CC Common Cathode | D7: 1 Inch Red 1BIT | E7: LED Merah Display Jam Digital Nilai Sensor | F7: 7-Segment Katoda 1" Inch 1inch BIT | G7: BisaElektronika - BisaSegment | H7: 3 | K7: ITBisa - Seven 7 Segment CC Common Cathode 1 Inch Red 1BIT LED Merah Display Jam Digital Nilai Sensor 7-Segment Katoda 1" Inch 1inch BIT | L7: ITBisa - Seven 7 Segment CC Common Cathode 1 Inch Red 1BIT LED Merah D | M7: ITBisa - Seven 7 Segment CC Common Cathode 1 Inch Red 1BIT LED Merah Display Jam Digital Nilai Sensor 7-Segment Katoda 1" Inch 1inch BIT | N7: ITBisa - Seven 7 Segment CC Common Cathode 1 Inch Red 1BIT LED Merah Display Jam Digital Nilai Sensor 7-Segment Katoda 1" Inch 1inch BIT
A8: ITBISA-7SEGMENT-CATHODE-RED-1.20-1BIT | B8: Seven 7 Segment | C8: CC Common Cathode | D8: 1.2 Inch Red 1BIT | E8: LED Merah Display Jam Digital Nilai Sensor | F8: 7-Segment Katoda 1,2" Inci 1.2" 1.2inch 1 BIT | G8: BisaElektronika - BisaSegment | H8: 3 | I8: #ITBisa #BisaElektronika #BisaSegment #7Segment #Segment #CA #CC #Anode #Cathode #0.56 #LED #1BIT #Red #Arduino #Counter #Digital #IC #Mikrokontroler #Timer #Clock | J8: 20 | K8: ITBisa - Seven 7 Segment CC Common Cathode 1.2 Inch Red 1BIT LED Merah Display Jam Digital Nilai Sensor 7-Segment Katoda 1,2" Inci 1.2" 1.2inch 1 BIT | L8: ITBisa - Seven 7 Segment CC Common Cathode 1.2 Inch Red 1BIT LED Merah | M8: ITBisa - Seven 7 Segment CC Common Cathode 1.2 Inch Red 1BIT LED Merah Display Jam Digital Nilai Sensor 7-Segment Katoda 1,2" Inci 1.2" 1.2inch 1 BIT | N8: ITBisa - Seven 7 Segment CC Common Cathode 1.2 Inch Red 1BIT LED Merah Display Jam Digital Nilai Sensor 7-Segment Katoda 1,2" Inci 1.2" 1.2inch 1 BIT
A9: ITBISA-7SEGMENT-CATHODE-RED-2.30-1BIT
A10: ITBISA-ABC-BATERAI-9V-ALKALINE
A11: ITBISA-ABC-BATERAI-9V-POWER
A12: ITBISA-ABC-BATERAI-AA-ALKALINE
A13: ITBISA-ABC-BATERAI-AAA-ALKALINE
A14: ITBISA-ABC-BATERAI-D-ALKALINE
A15: ITBISA-ABC-BATERAI-D-BIRU | B15: Baterai ABC | C15: Standar 1,5 V | D15: Size D Biru | F15: Batre Biasa 1,5V 1.5V 1.5 Volt Ukuran D Warna Blue | G15: BisaOspek | H15: 100 | I15: #ITBisa #BisaOspek #BisaBaterai #Ospek #Baterai #ABC #D #Size #1.5V #Volt #Senter #Big #Jumbo #Power #Alkaline #Carbon #Zinc #Karbon #Galon #Jumbo | J15: 20 | K15: ITBisa - Baterai ABC Standar 1,5 V Size D Biru Batre Biasa 1,5V 1.5V 1.5 Volt Ukuran D Warna Blue | L15: ITBisa - Baterai ABC Standar 1,5 V Size D Biru Batre Biasa 1,5V 1.5V 1 | M15: ITBisa - Baterai ABC Standar 1,5 V Size D Biru Batre Biasa 1,5V 1.5V 1.5 Volt Ukuran D Warna Blue | N15: ITBisa - Baterai ABC Standar 1,5 V Size D Biru Batre Biasa 1,5V 1.5V 1.5 Volt Ukuran D Warna Blue
A16: ITBISA-ABC-BATERAI-D-POWER | B16: Baterai ABC Size D | C16: Super Power Heavy Duty DR20P | D16: 1.5V Jumbo Carbon Zinc Hitam | E16: Senter Pompa Galon | F16: Batre Jumbo Karbon Tipe D R20P Besar 1,5V 1.5V 1.5 Volt Type Ukuran D Warna Black | G16: BisaOspek | H16: 100 | I16: #ITBisa #BisaOspek #BisaBaterai #Ospek #Baterai #ABC #D #Size #1.5V #Volt #Senter #Big #Jumbo #Power #Alkaline #Carbon #Zinc #Karbon #Galon #Jumbo | J16: 20 | K16: ITBisa - Baterai ABC Size D Super Power Heavy Duty DR20P 1.5V Jumbo Carbon Zinc Hitam Senter Pompa Galon Batre Jumbo Karbon Tipe D R20P Besar 1,5V 1.5V 1.5 Volt Type Ukuran D Warna Black | L16: ITBisa - Baterai ABC Size D Super Power Heavy Duty DR20P 1.5V Jumbo Ca | M16: ITBisa - Baterai ABC Size D Super Power Heavy Duty DR20P 1.5V Jumbo Carbon Zinc Hitam Senter Pompa Galon Batre Jumbo Karbon Tipe D R20P Besar 1,5V 1.5 | N16: ITBisa - Baterai ABC Size D Super Power Heavy Duty DR20P 1.5V Jumbo Carbon Zinc Hitam Senter Pompa Galon Batre Jumbo Karbon Tipe D R20P Besar 1,5V 1.5V 1.5 Volt Type Ukuran D Warna Black
A17: ITBISA-ABC-SENTER-LED-ALKALINE | B17: Senter ABC Alkaline | C17: LED Multifungsi | E17: Emergency Light | F17: Multifunction LED Lights | G17: BisaSenter | H17: 300 | I17: #ITBisa #BisaOspek #BisaSenter #Ospek #Baterai #ABC #AAA | J17: 7 | K17: ITBisa - Senter ABC Alkaline LED Multifungsi Emergency Light Multifunction LED Lights | L17: ITBisa - Senter ABC Alkaline LED Multifungsi Emergency Light Multifunc | M17: ITBisa - Senter ABC Alkaline LED Multifungsi Emergency Light Multifunction LED Lights | N17: ITBisa - Senter ABC Alkaline LED Multifungsi Emergency Light Multifunction LED Lights | O17: https://www.bukalapak.com/p/elektronik/komponen-elektronik/163beu6-jual-itbisa-40pcs-kabel-jumper-10-cm-male-to-female-m-f-2-54-mm-merk-dupont-arduino-breadboard-40-pcs-buah-mf-m-f-pin-2-54mm-10cm-cable | P17: https://www.tokopedia.com/itbisa/itbisa-40pcs-kabel-jumper-10-cm-male-to-female-m-f-2-54-mm-mf-10cm | Q17: https://shopee.co.id/product/80492423/2291036855/
A18: ITBISA-ARDUINO-UNO-R3-328P-SMD | B18: Arduino | C18: UNO R3 CH340G SMD ATMega328P | D18: Clone Only No Cable | E18: Mikrokontroler | F18: Tanpa Kabel USB ATMega328 AT Mega Kloning Duplikat Microcontroller | G18: BisaElektronika | K18: ITBisa - Arduino UNO R3 CH340G SMD ATMega328P Clone Only No Cable Mikrokontroler Tanpa Kabel USB ATMega328 AT Mega Kloning Duplikat Microcontroller | L18: ITBisa - Arduino UNO R3 CH340G SMD ATMega328P Clone Only No Cable Mikr | M18: ITBisa - Arduino UNO R3 CH340G SMD ATMega328P Clone Only No Cable Mikrokontroler Tanpa Kabel USB ATMega328 AT Mega Kloning Duplikat Microcontroller | N18: ITBisa - Arduino UNO R3 CH340G SMD ATMega328P Clone Only No Cable Mikrokontroler Tanpa Kabel USB ATMega328 AT Mega Kloning Duplikat Microcontroller | O18: https://www.bukalapak.com/p/elektronik/komponen-elektronik/1b2qbb9-jual-itbisa-transistor-bjt-npn-2n2222a-h331-to92-0-6a-30v-penguat-switch-transistors-2n2222-2n-2222-a-to-92-h-331-0-6-op-amp-switching-30-v-30volt | P18: https://www.tokopedia.com/itbisa/itbisa-transistor-bjt-npn-2n2222-a-2n2222a-h331-penguat-switch-to92 | Q18: https://shopee.co.id/product/80492423/2291143520/
A19: ITBISA-ARDUINO-UNO-R3-CLONE-CABLE30CM | B19: Arduino | C19: UNO R3 CH340G SMD | D19: Clone Plus + USB Kabel 30CM Cable 30 CM ATMega328P | E19: Mikrokontroler | F19: ATMega328 AT Mega 328 P + Cable Kloning Duplikat Microcontroller | G19: BisaElektronika | K19: ITBisa - Arduino UNO R3 CH340G SMD Clone Plus + USB Kabel 30CM Cable 30 CM ATMega328P Mikrokontroler ATMega328 AT Mega 328 P + Cable Kloning Duplikat Microcontroller | L19: ITBisa - Arduino UNO R3 CH340G SMD Clone Plus + USB Kabel 30CM Cable 3 | M19: ITBisa - Arduino UNO R3 CH340G SMD Clone Plus + USB Kabel 30CM Cable 30 CM ATMega328P Mikrokontroler ATMega328 AT Mega 328 P + Cable Kloning Duplikat | N19: ITBisa - Arduino UNO R3 CH340G SMD Clone Plus + USB Kabel 30CM Cable 30 CM ATMega328P Mikrokontroler ATMega328 AT Mega 328 P + Cable Kloning Duplikat Microcontroller
A20: ITBISA-ARDUINO-UNO-R3-CLONE-CABLE50CM | B20: Arduino | C20: UNO R3 CH340G ATMega328P SMD | D20: Clone Plus USB Kabel 50CM | E20: Mikrokontroler | F20: ATMega328 AT Mega 328 P + Cable 50 cm Kloning Duplikat Microcontroller | G20: BisaElektronika | K20: ITBisa - Arduino UNO R3 CH340G ATMega328P SMD Clone Plus USB Kabel 50CM Mikrokontroler ATMega328 AT Mega 328 P + Cable 50 cm Kloning Duplikat Microcontroller | L20: ITBisa - Arduino UNO R3 CH340G ATMega328P SMD Clone Plus USB Kabel 50C | M20: ITBisa - Arduino UNO R3 CH340G ATMega328P SMD Clone Plus USB Kabel 50CM Mikrokontroler ATMega328 AT Mega 328 P + Cable 50 cm Kloning Duplikat Microcon | N20: ITBisa - Arduino UNO R3 CH340G ATMega328P SMD Clone Plus USB Kabel 50CM Mikrokontroler ATMega328 AT Mega 328 P + Cable 50 cm Kloning Duplikat Microcontroller
A21: ITBISA-BLUETOOTH-MODULE-HC05
A22: ITBISA-BREADBOARD-830HOLE-MB102
A23: ITBISA-BUBBLE-WRAP
A24: ITBISA-BUKAEMAS
A25: ITBISA-BUKAREKSA-BAHANA-MES-SYARIAH | O25: https://www.bukalapak.com/p/elektronik/komponen-elektronik/1p5d40c-jual-itbisa-40pcs-kabel-jumper-10-cm-female-to-female-f-f-2-54-mm-merk-dupont-arduino-breadboard-40-pcs-buah-ff-f-f-pin-2-54mm-10cm-cable | P25: https://www.tokopedia.com/itbisa/itbisa-40pcs-kabel-jumper-10-cm-female-to-female-f-f-2-54-mm-ff-10cm | Q25: https://shopee.co.id/product/80492423/2287703561/
A26: ITBISA-BUKAREKSA-CIMB-PRINCIPAL-PASAR-UANG | O26: https://www.bukalapak.com/p/elektronik/komponen-elektronik/2aposh9-jual-itbisa-socket-ic-dip-8-2x4-narrow-soket-integrated-circuit-8-pin-kaki-lubang-datar-dip8-8dip | P26: https://tokopedia.com/itbisa/itbisa-socket-ic-dip-8-2x4-narrow-soket-dip8-8dip-8-dip-pin-kaki | Q26: https://shopee.co.id/product/80492423/2287659492/
A27: ITBISA-BUKAREKSA-CIPTA-SYARIAH-BALANCE
A28: ITBISA-BUKAREKSA-MANDIRI-INVESTA-DANA-SYARIAH
A29: ITBISA-BUKAREKSA-MANDIRI-INVESTA-PASAR-UANG
A30: ITBISA-BUKAREKSA-SUCORINVEST-SHARIA-EQUITY-FUND | O30: https://www.bukalapak.com/p/elektronik/komponen-elektronik/3ge7cl1-jual-itbisa-socket-ic-dip16-2x8-narrow-dip-16-pin-16p-soket-dip-16-2-54mm-2-54-mm-dudukan-16-lubang-16-dip-integrated-integrate-circuit-2-x-8-8x2-8-x-2 | P30: https://tokopedia.com/itbisa/itbisa-socket-ic-dip16-2x8-narrow-dip-16-pin-16p-soket-dip-16-2-54mm
A31: ITBISA-BUKAREKSA-SYARIAH-MANDIRI-PASAR-UANG | O31: https://www.bukalapak.com/p/elektronik/komponen-elektronik/3t18497-jual-itbisa-40pcs-kabel-jumper-20-cm-male-to-male-m-m-mm-m-m-2-54mm-arduino-breadboard-40-pcs-20cm-buah-pin-2-54-mm-wire-cable-rainbow-pelangi-sensor | P31: https://tokopedia.com/itbisa/itbisa-40pcs-kabel-jumper-20-cm-male-to-male-m-m-2-54-mm-mm-m-m-20cm | Q31: https://shopee.co.id/product/80492423/4855244491/
A32: ITBISA-BUZZER-ACTIVE-5V | O32: https://www.bukalapak.com/p/elektronik/komponen-elektronik/3t187p8-jual-itbisa-40pcs-kabel-jumper-20-cm-female-to-female-f-f-ff-f-f-2-54mm-arduino-breadboard-40-pcs-20cm-buah-pin-2-54-mm-wire-cable-rainbow-pelangi-sensor | P32: https://www.tokopedia.com/itbisa/itbisa-40pcs-kabel-jumper-20-cm-female-to-female-f-f-2-54-mm-ff-20cm | Q32: https://shopee.co.id/product/80492423/5655241072/
A33: ITBISA-CHIP-ESP32-WROOM | O33: https://www.bukalapak.com/p/elektronik/komponen-elektronik/vbuzpu-jual-itbisa-40pcs-kabel-jumper-10-cm-male-to-male-m-m-2-54-mm-merk-dupont-arduino-breadboard-40-pcs-buah-mm-m-m-pin-2-54mm-10cm-cable | P33: https://www.tokopedia.com/itbisa/itbisa-40pcs-kabel-jumper-10-cm-male-to-male-m-m-2-54-mm-mm-m-m-10cm | Q33: https://shopee.co.id/product/80492423/2291050648/
A34: ITBISA-CHIP-ESP32-WROOM-ANTENNA
A35: ITBISA-CHIP-ESP8266-ESP12F
A36: ITBISA-CORSAIR-VENGEANCE-K66
A37: ITBISA-DC-TO-DC-STEPDOWN-LM2596
A38: ITBISA-DC-TO-DC-STEPDOWN-XL4005
A39: ITBISA-DC-TO-DC-STEPDOWN-XL4015 | P39: https://www.tokopedia.com/itbisa/itbisa-seven-7-segment-ca-common-anode-0-56-inch-red-1bit-led-merah
A40: ITBISA-DC-TO-DC-STEPUP-XL6009
...

Sheet BisaEtalase
A1: Level 1 | B1: Level 2
A2: Elektronika
B3: IC
B4: Induktor
B5: Kabel
B6: Kapasitor
B7: Lampu
B8: Mikrokontroler
B9: PCB
B10: Resistor
B11: Segment
B12: Socket
B13: Transistor
A14: Ospek
B15: Lampu
B16: Sarung Tangan
B17: Senter
B18: Syal
B19: Baterai

Sheet BisaPerlengkapan
A1: Tanggal Beli | B1: Jenis Transaksi Debit | C1: Jenis Transaksi Kredit | D1: Nominal | E1: Keterangan
A3: 46023.008 | B3: Perlengkapan Kardus | C3: Kas ITBisa | D3: =80*250 - 4000 + 1000 -> 17000 | E3: 80 x Kardus 12x6x6 - KARDUS MOUD Shopee
A4: 46048.586 | B4: Perlengkapan Tinta | C4: Kas ITBisa | D4: =(98000 + 3100 - 10000 + 1000) -> 92100 | E4: 1 x Tinta EPSON Hitam L3110
A6: 46128.061 | B6: Perlengkapan Selotip | C6: Kas ITBisa | D6: =(2*48600 + 1*48600 + 56000 - 55000 - 29160 + 2200) -> 119840 | E6: Lakban 48mm x 90 yard (2 x 6 Cokelat BAGUS + 2 x 1 Bening JELEK)
A7: 46142.66 | B7: Perlengkapan Bubble Wrap | C7: Kas ITBisa | D7: =(129900 + 14000 - 14000 - 15000 + 2200) -> 117100 | E7: Bubble Wrap Hitam 3 kg Non Core
A9: 45782.901 | B9: Perlengkapan Gunting | C9: Kas ITBisa | D9: =(14500 + 8000 - 8000 - 5000 + 1500) -> 11000 | E9: 1 x Gunting Joyko Besar - JURAGAN ATK Official Shopee
A10: 46147.75 | B10: Perlengkapan Plastik Klip | C10: Kas ITBisa | D10: =(56250 + 6500 - 6500 - 4000 + 2000) -> 54250 | E10: 1 x 1000 Plastik Klip - majuplastic Shopee
A11: 46152.705 | B11: Perlengkapan Selotip | C11: Kas ITBisa | D11: =(28500 + 8000 - 8000 - 4000 + 2000) -> 26500 | E11: 6 x Lakban Cokelat 45mm x 90 yard - SUPER LIGHTING Shopee
A12: 46152.697 | B12: Perlengkapan Selotip | C12: Kas ITBisa | D12: =(583200 + 48900 - 48900 - 58320 + 3000) -> 527880 | E12: 72 x Lakban Cokelat 45mm x 90 yard - kilatpacking Shopee
A14: 46158.592 | B14: Perlengkapan Tape Cutter | C14: Kas ITBisa | D14: =(3*7200) - 2160 + 66 -> 19506 | E14: 3 x Tape Cutter 2 Inch - Andalan Packing Shopee
A15: 46159.726 | B15: Perlengkapan Kardus | C15: Kas ITBisa | D15: =54426+21999-21999+10000-10885+435 -> 53976 | E15: 193 x Kardus/Karton Box Packing 12x6x6 - ID karton Shopee
A16: 46159.726 | B16: Perlengkapan Kardus | C16: Kas ITBisa | D16: =95550+28000-28000+5000-19111+765 -> 82204 | E16: 390 x Karton Packing 12x6x6 - i Box Shopee
A17: 46168.515 | B17: Perlengkapan Kardus | C17: Kas ITBisa | D17: =21999+25200-25200-4000+1000 -> 18999 | E17: 1 x Kardus 1-5 kg bekas Ale Ale 3Kg - PUSAT OLEH-OLEH BREBES.ID Shopee
A18: 46168.518 | B18: Perlengkapan Bubble Wrap | C18: Kas ITBisa | D18: =127000+39000-39000-10795-19050+2000 -> 99155 | E18: 1 x Bubble Wrap Hitam Standard 125cm x 50M - sipacking Shopee
A20: 46193.699 | B20: Perlengkapan Kardus | C20: Kas ITBisa | D20: =21999+25200-25200-4399+323 -> 17923 | E20: 1 x Kardus 1-5 Kg bekas Ale Ale 3Kg - PUSAT OLEH-OLEH BREBES.ID - 260620JUFJQBW4
A21: 46193.699 | B21: Perlengkapan Selotip | C21: Kas ITBisa | D21: =127800+22500-22500-25561+1877 -> 104116 | E21: 2 x Lakban Solasi Cortape Plakban Selotip Cokelat 48mm x 90yard + 1 x Lakban Solasi Cortape Plakban Selotip Bening 48mm x 90yard - kilatpacking - 260620JUFJQBW3
A22: 46190.592 | B22: Perlengkapan Tinta | C22: Kas ITBisa | D22: =588000+6300-2000-58800+3000 -> 536500 | E22: 1 x Epson Tinta 003 1 set (Paket 4 warna) + 2 x Tinta Epson 003 Black Original - Epson Official Store Indonesia - 260617B1GDURYV

Sheet BisaJurnal
A1: {={"Tanggal Akun","Akun","Referensi (Kode Transaksi)","Debit","Kredit","Keterangan"; SORT({ IF((BisaStok!B3:B5017<2),,{BisaStok!B3:B5017+0.00001*MOD(ROW(BisaStok!B3:B5017),100), "Piutang "&BisaStok!F3:F5017,IF(BisaStok!B3:B5017<2,,"PIU-BisaStok-"&TEXT(ROW(BisaStok!B3:B5017),"00000")),BisaStok!AB3:AB5017,SUBSTITUTE(BisaStok!B3:B5017,BisaStok!B3:B5017,),BisaStok!H3:H5017}); IF((BisaStok!B3:B5017<2),,{BisaStok!B3:B5017+0.00001*MOD(ROW(BisaStok!B3:B5017),100), " Kas ITBisa"&SUBSTITUTE(BisaStok!B3:B5017,BisaStok!B3:B5017,),IF(BisaStok!B3:B5017<2,,"KAS-BisaStok-"&TEXT(ROW(BisaStok!B3:B5017),"00000")),SUBSTITUTE(BisaStok!B3:B5017,BisaStok!B3:B5017,),BisaStok!AB3:AB5017,BisaStok!H3:H5017}); IF((BisaStok!C3:C5017<2),,{BisaStok!C3:C5017+0.00001*MOD(ROW(BisaStok!C3:C5017),100), "Persediaan "&BisaStok!A3:A5017,IF(BisaStok!B3:B5017<2,,"INV-BisaStok-"&TEXT(ROW(BisaStok!B3:B5017),"00000")),BisaStok!AB3:AB5017,SUBSTITUTE(BisaStok!B3:B5017,BisaStok!B3:B5017,),BisaStok!H3:H5017}); IF((BisaStok!C3:C5017<2),,{BisaStok!C3:C5017+0.00001*MOD(ROW(BisaStok!C3:C5017),100), " Piutang "&BisaStok!F3:F5017,IF(BisaStok!B3:B5017<2,,"PIU-BisaStok-"&TEXT(ROW(BisaStok!B3:B5017),"00000")),SUBSTITUTE(BisaStok!B3:B5017,BisaStok!B3:B5017,),BisaStok!AB3:AB5017,BisaStok!H3:H5017}); "","","","","",""; IF((BisaPerlengkapan!A2:A5017<2),,{BisaPerlengkapan!A2:A5017+0.00001*MOD(ROW(BisaPerlengkapan!A2:A5017),100),BisaPerlengkapan!B2:B5017,"DBT-BisaPerlengkapan-"&TEXT(ROW(BisaPerlengkapan!A2:A5017),"00000"),BisaPerlengkapan!D2:D5017,SUBSTITUTE(BisaPerlengkapan!A2:A5017,BisaPerlengkapan!A2:A5017,),BisaPerlengkapan!E2:E5017}); IF((BisaPerlengkapan!A2:A5017<2),,{BisaPerlengkapan!A2:A5017+0.00001*MOD(ROW(BisaPerlengkapan!A2:A5017),100), " "&BisaPerlengkapan!C2:C5017,"CRT-BisaPerlengkapan-"&TEXT(ROW(BisaPerlengkapan!A2:A5017),"00000"),SUBSTITUTE(BisaPerlengkapan!A2:A5017,BisaPerlengkapan!A2:A5017,),BisaPerlengkapan!D2:D5017,BisaPerlengkapan!E2:E5017}); "","","","","",""; IF((BisaHilang!A2:A5017<2)+(BisaHilang!C2:C5017<1)+(BisaHilang!D2:D5017<1),,{BisaHilang!A2:A5017+0.00001*MOD(ROW(BisaHilang!A2:A5017),100),"Persediaan "&BisaHilang!B2:B5017,"INV-BisaHilang-"&TEXT(ROW(BisaHilang!A2:A5017),"00000"),BisaHilang!D2:D5017,SUBSTITUTE(BisaHilang!A2:A5017,BisaHilang!A2:A5017,),SUBSTITUTE(BisaHilang!A2:A5017,BisaHilang!A2:A5017,)}); IF((BisaHilang!A2:A5017<2)+(BisaHilang!C2:C5017<1)+(BisaHilang!D2:D5017<1),,{BisaHilang!A2:A5017+0.00001*MOD(ROW(BisaHilang!A2:A5017),100)," Bonus "&BisaHilang!B2:B5017,"BNS-BisaHilang-"&TEXT(ROW(BisaHilang!A2:A5017),"00000"),SUBSTITUTE(BisaHilang!A2:A5017,BisaHilang!A2:A5017,),BisaHilang!D2:D5017,SUBSTITUTE(BisaHilang!A2:A5017,BisaHilang!A2:A5017,)}); "","","","","",""; IF((BisaHilang!A2:A5017<2)+(BisaHilang!E2:E5017<1)+(BisaHilang!F2:F5017<1),,{BisaHilang!A2:A5017+0.00001*MOD(ROW(BisaHilang!A2:A5017),100),"Beban Hilang "&BisaHilang!B2:B5017,"BBN-BisaHilang-"&TEXT(ROW(BisaHilang!A2:A5017),"00000"),BisaHilang!F2:F5017,SUBSTITUTE(BisaHilang!A2:A5017,BisaHilang!A2:A5017,),SUBSTITUTE(BisaHilang!A2:A5017,BisaHilang!A2:A5017,)}); IF((BisaHilang!A2:A5017<2)+(BisaHilang!E2:E5017<1)+(BisaHilang!F2:F5017<1),,{BisaHilang!A2:A5017+0.00001*MOD(ROW(BisaHilang!A2:A5017),100)," Persediaan "&BisaHilang!B2:B5017,"INV-BisaHilang-"&TEXT(ROW(BisaHilang!A2:A5017),"00000"),SUBSTITUTE(BisaHilang!A2:A5017,BisaHilang!A2:A5017,),BisaHilang!F2:F5017,SUBSTITUTE(BisaHilang!A2:A5017,BisaHilang!A2:A5017,)}); "","","","","",""},1,TRUE)}} -> Tanggal Akun | B1: Akun | C1: Referensi (Kode Transaksi) | D1: Debit | E1: Kredit | F1: Keterangan
A2: 43590.408 | B2: Piutang Migrasi - Shopee | C2: PIU-BisaStok-00004 | D2: 27113.1 | F2: Shopee Furqonajiy 19050510476HUJK ( - ) Mahal ( + ) Untuk Testing Darurat Pesan (?) setiap 10 buah diberi strefoam
A3: 43590.408 | B3: Kas ITBisa | C3: KAS-BisaStok-00004 | E3: 27113.1 | F3: Shopee Furqonajiy 19050510476HUJK ( - ) Mahal ( + ) Untuk Testing Darurat Pesan (?) setiap 10 buah diberi strefoam
A4: 43596 | B4: Persediaan ITBISA-IC-LM741CN-DIP8 | C4: INV-BisaStok-00004 | D4: 27113.1 | F4: Shopee Furqonajiy 19050510476HUJK ( - ) Mahal ( + ) Untuk Testing Darurat Pesan (?) setiap 10 buah diberi strefoam
A5: 43596 | B5: Piutang Migrasi - Shopee | C5: PIU-BisaStok-00004 | E5: 27113.1 | F5: Shopee Furqonajiy 19050510476HUJK ( - ) Mahal ( + ) Untuk Testing Darurat Pesan (?) setiap 10 buah diberi strefoam
A6: 44032 | B6: Piutang Migrasi - Tokopedia | C6: PIU-BisaStok-00005 | D6: 21981.4 | F6: Tokopedia Furqonajiy
A7: 44032 | B7: Kas ITBisa | C7: KAS-BisaStok-00005 | E7: 21981.4 | F7: Tokopedia Furqonajiy
A8: 44039 | B8: Persediaan ITBISA-RESISTOR-470K-1/4W | C8: INV-BisaStok-00005 | D8: 21981.4 | F8: Tokopedia Furqonajiy
A9: 44039 | B9: Piutang Migrasi - Tokopedia | C9: PIU-BisaStok-00005 | E9: 21981.4 | F9: Tokopedia Furqonajiy
A10: 44039 | B10: Piutang Migrasi - Tokopedia | C10: PIU-BisaStok-00006 | D10: 13000 | F10: Tokopedia Furqonajiy
A11: 44039 | B11: Kas ITBisa | C11: KAS-BisaStok-00006 | E11: 13000 | F11: Tokopedia Furqonajiy
A12: 44041 | B12: Persediaan ITBISA-RESISTOR-56K-1/4W | C12: INV-BisaStok-00006 | D12: 13000 | F12: Tokopedia Furqonajiy
